Workbook
Name TGT_FS_promo: '01_Нормативы'!$C$4
Name TGT_FS_reg: '01_Нормативы'!$C$5
Name TGT_RDC: '01_Нормативы'!$C$6
Name TGT_FT: '01_Нормативы'!$C$7
Name TGT_EK: '01_Нормативы'!$C$8
Name TGT_KPi: '01_Нормативы'!$C$9
Name TGT_Ecom: '01_Нормативы'!$C$10
Name TGT_RKP: '01_Нормативы'!$C$11

Sheet 00_Как_читать
A1: ТЕСТ DEMAND — РАБОЧАЯ ТЕТРАДЬ С ФОРМУЛАМИ
A3: ЭТОТ ФАЙЛ — С ФОРМУЛАМИ (не с забитыми ответами)
A5: Синие ячейки = исходные данные (значения из ТЗ, их не надо выдумывать).
A6: Зелёные ячейки = ФОРМУЛЫ Excel. Кликни ячейку и смотри строку формул.
A7: Жёлтые = пояснения / нормативы.
A8: Оранжевые = дефицит (статус считается формулой).
A10: Листы:
A11: 01_Нормативы — цели каналов в тоннах и кг (для ссылок в формулах).
A12: 02_Данные — вход: остаток, выпуск по неделям, прогноз по каналам/неделям.
A13: 03_Расчёт — вся логика формулами: доступно, приоритет каналов, недельный перенос, план мес, урезка до лимита канала.
A14: 04_Сводка — СУММ планов vs цели (формулы).
A15: 05_Дефицит — список через формулы/фильтр (статус на листе 03).
... A23: Лимит канала (кг) = тонны * 1000 из листа 01_Нормативы.

Sheet 01_Нормативы
A1: Целевые планы каналов (из шапки ТЗ)
A3: Канал | B3: Цель_тонн | C3: Цель_кг | D3: Имя_ячейки_кг
A4: ФС промо | B4: 7358 | C4: =B4*1000 | D4: Цель_FS_promo
A5: ФС рег | B5: 1582 | C5: =B5*1000 | D5: Цель_FS_reg
A6: РДЦ | B6: 5373 | C6: =B6*1000 | D6: Цель_RDC
A7: ФТ | B7: 586 | C7: =B7*1000 | D7: Цель_FT
A8: ЭК | B8: 1300 | C8: =B8*1000 | D8: Цель_EK
A9: КПи | B9: 748 | C9: =B9*1000 | D9: Цель_KPi
A10: E-commerce | B10: 530 | C10: =B10*1000 | D10: Цель_Ecom
A11: РКП | B11: 2686.5 | C11: =B11*1000 | D11: Цель_RKP
A12: ИТОГО | B12: =SUM(B4:B11) | C12: =SUM(C4:C11)
A14: Приоритет (порядок раздачи при дефиците) — номер меньше = важнее
A15: 1 | B15: ФС промо
A16: 2 | B16: ФС рег
A17: 3 | B17: РДЦ
A18: 4 | B18: РКП
A19: 5 | B19: ЭК
A20: 6 | B20: ФТ
A21: 7 | B21: КПи
A22: 8 | B22: E-commerce

Sheet 02_Данные
A1: Строка_ТЗ | B1: Код | C1: Наименование | D1: Категория | E1: Тип | F1: Остаток_нач | G1: Выпуск_н1 | H1: Выпуск_н2 | I1: Выпуск_н3 | J1: Выпуск_н4 | K1: Выпуск_н5 | L1: Прг_н1_ФС промо | M1: Прг_н1_ФС рег | N1: Прг_н1_РДЦ | O1: Прг_н1_ФТ | P1: Прг_н1_ЭК | Q1: Прг_н1_КПи | R1: Прг_н1_E-commerce | S1: Прг_н1_РКП | T1: Прг_н2_ФС промо | U1: Прг_н2_ФС рег | V1: Прг_н2_РДЦ | W1: Прг_н2_ФТ | X1: Прг_н2_ЭК | Y1: Прг_н2_КПи | Z1: Прг_н2_E-commerce | AA1: Прг_н2_РКП | AB1: Прг_н3_ФС промо | AC1: Прг_н3_ФС рег | AD1: Прг_н3_РДЦ | AE1: Прг_н3_ФТ | AF1: Прг_н3_ЭК | AG1: Прг_н3_КПи | AH1: Прг_н3_E-commerce | AI1: Прг_н3_РКП | AJ1: Прг_н4_ФС промо | AK1: Прг_н4_ФС рег | AL1: Прг_н4_РДЦ | AM1: Прг_н4_ФТ | AN1: Прг_н4_ЭК | AO1: Прг_н4_КПи | AP1: Прг_н4_E-commerce | AQ1: Прг_н4_РКП | AR1: Прг_н5_ФС промо | AS1: Прг_н5_ФС рег | AT1: Прг_н5_РДЦ | AU1: Прг_н5_ФТ | AV1: Прг_н5_ЭК | AW1: Прг_н5_КПи | AX1: Прг_н5_E-commerce | AY1: Прг_н5_РКП
A2: 8 | B2: ЮК207 | D2: МУЧНЫЕ | E2: Федеральный | F2: 63965.8 | G2: 0 | H2: 4367.95 | I2: 14162.16 | J2: 7733.91 | K2: 0 | L2: 3807 | M2: 447.64488 | N2: 1103.9835 | O2: 126.44 | P2: 0 | Q2: 1.3869384 | R2: 244.58289 | S2: 0 | T2: 6521 | U2: 1134.3068 | V2: 2712.3896 | W2: 130.94 | X2: 0 | Y2: 3.0646983 | Z2: 727.45751 | AA2: 0 | AB2: 9537 | AC2: 1020.5081 | AD2: 3658.4043 | AE2: 138.54 | AF2: 0 | AG2: 4.56411 | AH2: 566.16042 | AI2: 0 | AJ2: 9949 | AK2: 1004.7512 | AL2: 3667.6594 | AM2: 129.99 | AN2: 0 | AO2: 4.1102543 | AP2: 61.023736 | AQ2: 0 | AR2: 8483.8 | AS2: 937.21693 | AT2: 3581.3845 | AU2: 124.29 | AV2: 0 | AW2: 0.6934692 | AX2: 9.0423722 | AY2: 0
A3: 9 | B3: ЮК207 | D3: МУЧНЫЕ | E3: Федеральный | F3: 10424.4 | G3: 0 | H3: 3455.58 | I3: 1288.59 | J3: 0 | K3: 0 | L3: 0 | M3: 88.594243 | N3: 255.82791 | O3: 0 | P3: 0 | Q3: 3.8862175 | R3: 16.941387 | S3: 0 | T3: 0 | U3: 124.64633 | V3: 923.09621 | W3: 0 | X3: 0 | Y3: 8.5873204 | Z3: 49.127097 | AA3: 0 | AB3: 0 | AC3: 179.8651 | AD3: 1330.207 | AE3: 0 | AF3: 0 | AG3: 12.788689 | AH3: 47.127234 | AI3: 0 | AJ3: 0 | AK3: 221.61465 | AL3: 1335.7591 | AM3: 0 | AN3: 0 | AO3: 11.516981 | AP3: 29.375719 | AQ3: 0 | AR3: 0 | AS3: 44.297122 | AT3: 1436.0899 | AU3: 0 | AV3: 0 | AW3: 1.9431088 | AX3: 6.1484679 | AY3: 0
A4: 10 | B4: ЮК207 | D4: МУЧНЫЕ | E4: Федеральный | F4: 0 | G4: 0 | H4: 0 | I4: 0 | J4: 0 | K4: 0 | L4: 0 | M4: 0 | N4: 0 | O4: 0 | P4: 0 | Q4: 0 | R4: 0 | S4: 0 | T4: 0 | U4: 0 | V4: 0 | W4: 0 | X4: 0 | Y4: 0 | Z4: 0 | AA4: 0 | AB4: 0 | AC4: 0 | AD4: 0 | AE4: 0 | AF4: 0 | AG4: 0 | AH4: 0 | AI4: 0 | AJ4: 0 | AK4: 0 | AL4: 0 | AM4: 0 | AN4: 0 | AO4: 0 | AP4: 0 | AQ4: 0 | AR4: 0 | AS4: 0 | AT4: 0 | AU4: 0 | AV4: 0 | AW4: 0 | AX4: 0 | AY4: 0
A5: 11 | B5: ЮК218 | D5: МУЧНЫЕ | E5: Локальный | F5: 0 | G5: 0 | H5: 0 | I5: 0 | J5: 0 | K5: 0 | L5: 0 | M5: 0 | N5: 0 | O5: 0 | P5: 0 | Q5: 0 | R5: 0 | S5: 0 | T5: 0 | U5: 0 | V5: 0 | W5: 0 | X5: 0 | Y5: 0 | Z5: 0 | AA5: 0 | AB5: 0 | AC5: 0 | AD5: 0 | AE5: 0 | AF5: 0 | AG5: 0 | AH5: 0 | AI5: 0 | AJ5: 0 | AK5: 0 | AL5: 0 | AM5: 0 | AN5: 0 | AO5: 0 | AP5: 0 | AQ5: 0 | AR5: 0 | AS5: 0 | AT5: 0 | AU5: 0 | AV5: 0 | AW5: 0 | AX5: 0 | AY5: 0
A6: 12 | B6: ЮК207 | D6: МУЧНЫЕ | E6: Федеральный | F6: 9897.6 | G6: 0 | H6: 2064.185 | I6: 1524.29 | J6: 0 | K6: 0 | L6: 0 | M6: 15.272185 | N6: 411.32754 | O6: 15.36 | P6: 0 | Q6: 2.947199 | R6: 18.277363 | S6: 0 | T6: 0 | U6: 38.698852 | V6: 1061.071 | W6: 15.36 | X6: 0 | Y6: 6.5123843 | Z6: 48.425536 | AA6: 0 | AB6: 0 | AC6: 34.81641 | AD6: 1390.5505 | AE6: 15.36 | AF6: 0 | AG6: 9.6985853 | AH6: 48.951449 | AI6: 0 | AJ6: 0 | AK6: 37.178727 | AL6: 1411.2193 | AM6: 15.36 | AN6: 0 | AO6: 8.7341568 | AP6: 25.737179 | AQ6: 0 | AR6: 0 | AS6: 34.679763 | AT6: 1275.7083 | AU6: 15.36 | AV6: 0 | AW6: 1.4735995 | AX6: 1.1479037 | AY6: 0
A7: 13 | B7: ЮК207 | D7: МУЧНЫЕ | E7: Федеральный | F7: 7715.6 | G7: 5000 | H7: 2070.2 | I7: 7.24 | J7: 8.59 | K7: 0 | L7: 0 | M7: 0 | N7: 43.670807 | O7: 20 | P7: 0 | Q7: 0.72223645 | R7: 3.6268931 | S7: 0 | T7: 0 | U7: 0 | V7: 150.58403 | W7: 38 | X7: 0 | Y7: 1.5959157 | Z7: 9.4175105 | AA7: 0 | AB7: 0 | AC7: 0 | AD7: 209.91277 | AE7: 68.4 | AF7: 0 | AG7: 2.3767217 | AH7: 9.5197869 | AI7: 0 | AJ7: 0 | AK7: 0 | AL7: 207.90331 | AM7: 34.2 | AN7: 0 | AO7: 2.1403802 | AP7: 4.5716156 | AQ7: 0 | AR7: 0 | AS7: 0 | AT7: 154.16882 | AU7: 11.4 | AV7: 0 | AW7: 0.36111822 | AX7: 0 | AY7: 0
A8: 14 | B8: ЮК207 | D8: МУЧНЫЕ | E8: Федеральный | F8: 83.16 | G8: 0 | H8: 237.86 | I8: 104.07 | J8: 76.58 | K8: 0 | L8: 49 | M8: 0 | N8: 7.8898907 | O8: 0 | P8: 0 | Q8: 0 | R8: 0 | S8: 0 | T8: 84 | U8: 0 | V8: 26.021375 | W8: 0 | X8: 0 | Y8: 0 | Z8: 0 | AA8: 0 | AB8: 84 | AC8: 0 | AD8: 22.288696 | AE8: 0 | AF8: 0 | AG8: 0 | AH8: 0 | AI8: 0 | AJ8: 84 | AK8: 0 | AL8: 22.4078 | AM8: 0 | AN8: 0 | AO8: 0 | AP8: 0 | AQ8: 0 | AR8: 156 | AS8: 0 | AT8: 23.501418 | AU8: 0 | AV8: 0 | AW8: 0 | AX8: 0 | AY8: 0
A9: 15 | B9: ЮК207 | D9: МУЧНЫЕ | E9: Федеральный | F9: 4176.24 | G9: 0 | H9: 1958.47 | I9: 1935.79 | J9: 0 | K9: 0 | L9: 0 | M9: 0 | N9: 75.996158 | O9: 0 | P9: 0 | Q9: 1.3094017 | R9: 7.2537861 | S9: 0 | T9: 0 | U9: 0 | V9: 210.49211 | W9: 0 | X9: 0 | Y9: 2.8933665 | Z9: 18.835021 | AA9: 0 | AB9: 0 | AC9: 0 | AD9: 289.97487 | AE9: 0 | AF9: 0 | AG9: 4.3089536 | AH9: 19.039574 | AI9: 0 | AJ9: 0 | AK9: 0 | AL9: 292.69361 | AM9: 0 | AN9: 0 | AO9: 3.8804707 | AP9: 9.1432312 | AQ9: 0 | AR9: 0 | AS9: 0 | AT9: 212.85082 | AU9: 0 | AV9: 0 | AW9: 0.65470083 | AX9: 0 | AY9: 0
A10: 16 | B10: ЮК207 | D10: МУЧНЫЕ | E10: Федеральный | F10: 10719 | G10: 0 | H10: 79 | I10: 0 | J10: 0 | K10: 0 | L10: 95 | M10: 91.968808 | N10: 754.63616 | O10: 59.24 | P10: 0 | Q10: 8.1639971 | R10: 2.9741998 | S10: 0 | T10: 166 | U10: 233.04376 | V10: 1995.7011 | W10: 63.74 | X10: 0 | Y10: 18.03987 | Z10: 9.6534269 | AA10: 0 | AB10: 166 | AC10: 209.66377 | AD10: 2662.919 | AE10: 71.34 | AF10: 0 | AG10: 26.865923 | AH10: 7.8066123 | AI10: 0 | AJ10: 717 | AK10: 165.77338 | AL10: 2703.0541 | AM10: 62.79 | AN10: 0 | AO10: 24.194373 | AP10: 5.623366 | AQ10: 0 | AR10: 2081 | AS10: 154.63094 | AT10: 2676.1559 | AU10: 57.09 | AV10: 0 | AW10: 4.0819986 | AX10: 1.5280134 | AY10: 0
A11: 17 | B11: ЮК207 | D11: МУЧНЫЕ | E11: Федеральный | F11: 9491.475 | G11: 0 | H11: 1958.47 | I11: 1935.79 | J11: 0 | K11: 0 | L11: 240 | M11: 31.185003 | N11: 649.93673 | O11: 91.56 | P11: 0 | Q11: 1.1262362 | R11: 92.343851 | S11: 0 | T11: 257 | U11: 79.021034 | V11: 1427.7383 | W11: 91.56 | X11: 0 | Y11: 2.4886283 | Z11: 216.5507 | AA11: 0 | AB11: 81 | AC11: 71.09329 | AD11: 1895.5275 | AE11: 91.56 | AF11: 0 | AG11: 3.7061963 | AH11: 213.75753 | AI11: 0 | AJ11: 40 | AK11: 75.917017 | AL11: 1876.9765 | AM11: 91.56 | AN11: 0 | AO11: 3.3376517 | AP11: 19.600439 | AQ11: 0 | AR11: 37 | AS11: 70.814263 | AT11: 1645.5228 | AU11: 91.56 | AV11: 0 | AW11: 0.5631181 | AX11: 2.6085754 | AY11: 0
A12: 18 | B12: ЮК207 | D12: МУЧНЫЕ | E12: Федеральный | F12: 8636.65 | G12: 5900 | H12: 7030.34 | I12: 2324.42 | J12: 0 | K12: 0 | L12: 19 | M12: 0 | N12: 881.37219 | O12: 91.14 | P12: 0 | Q12: 1.3443061 | R12: 151.13414 | S12: 0 | T12: 33 | U12: 0 | V12: 1958.5722 | W12: 91.14 | X12: 0 | Y12: 2.9704944 | Z12: 326.0735 | AA12: 0 | AB12: 33 | AC12: 72.118488 | AD12: 2376.9471 | AE12: 91.14 | AF12: 0 | AG12: 4.4238165 | AH12: 349.84529 | AI12: 0 | AJ12: 79 | AK12: 0 | AL12: 2368.3132 | AM12: 91.14 | AN12: 0 | AO12: 3.9839117 | AP12: 27.431541 | AQ12: 0 | AR12: 131 | AS12: 0 | AT12: 1940.8469 | AU12: 91.14 | AV12: 0 | AW12: 0.67215306 | AX12: 3.5029948 | AY12: 0
A13: 19 | B13: СБ105 | D13: МУЧНЫЕ | E13: Федеральный | F13: 39333.75 | G13: 0 | H13: 31553.79 | I13: 23061.51 | J13: 21060.55 | K13: 10974.44 | L13: 17210 | M13: 246.67788 | N13: 1966.2104 | O13: 181.6 | P13: 0 | Q13: 5.6497121 | R13: 479.89323 | S13: 0.26366463 | T13: 7946.5 | U13: 586.71921 | V13: 5188.2934 | W13: 190.6 | X13: 0 | Y13: 12.48409 | Z13: 1572.5546 | AA13: 0.52732926 | AB13: 7358.5 | AC13: 530.36502 | AD13: 6256.5642 | AE13: 205.8 | AF13: 0 | AG13: 18.591963 | AH13: 1221.6272 | AI13: 0.84372682 | AJ13: 7938.5 | AK13: 563.63732 | AL13: 6322.3901 | AM13: 188.7 | AN13: 0 | AO13: 16.743176 | AP13: 636.79757 | AQ13: 1.1711245 | AR13: 8628 | AS13: 522.80999 | AT13: 6417.1768 | AU13: 177.3 | AV13: 0 | AW13: 2.824856 | AX13: 97.434548 | AY13: 0.52732926
... A429: 435 | B429: КО137 | D429: ШОКОЛАД | E429: Федеральный | F429: 0 | G429: 0 | H429: 0 | I429: 0 | J429: 0 | K429: 0 | L429: 0 | M429: 0 | N429: 0 | O429: 0 | P429: 0 | Q429: 0 | R429: 0 | S429: 0 | T429: 0 | U429: 0 | V429: 0 | W429: 0 | X429: 0 | Y429: 0 | Z429: 0 | AA429: 0 | AB429: 0 | AC429: 0 | AD429: 0 | AE429: 0 | AF429: 0 | AG429: 0 | AH429: 0 | AI429: 0 | AJ429: 0 | AK429: 0 | AL429: 0 | AM429: 0 | AN429: 0 | AO429: 0 | AP429: 0 | AQ429: 0 | AR429: 0 | AS429: 0 | AT429: 0 | AU429: 0 | AV429: 0 | AW429: 0 | AX429: 0 | AY429: 0

Sheet 03_Расчёт
A1: Код | B1: Тип | C1: Доступно_всего | D1: Спрос_всего | E1: Дефицит_кг | F1: Статус | G1: Сырой_ФС промо | H1: Сырой_ФС рег | I1: Сырой_РДЦ | J1: Сырой_ФТ | K1: Сырой_ЭК | L1: Сырой_КПи | M1: Сырой_E-commerce | N1: Сырой_РКП | O1: Сырой_Итого | P1: План_ФС промо | Q1: План_ФС рег | R1: План_РДЦ | S1: План_ФТ | T1: План_ЭК | U1: План_КПи | V1: План_E-commerce | W1: План_РКП | X1: План_Итого | Y1: Остаток_после | Z1: Fill_rate_% | AA1: Н1_Доступно | AB1: Н1_План_ФС промо | AC1: Н1_Ост_после_1 | AD1: Н1_План_ФС рег | AE1: Н1_Ост_после_2 | AF1: Н1_План_РДЦ | AG1: Н1_Ост_после_3 | AH1: Н1_План_РКП | AI1: Н1_Ост_после_4 | AJ1: Н1_План_ЭК | AK1: Н1_Ост_после_5 | AL1: Н1_План_ФТ | AM1: Н1_Ост_после_6 | AN1: Н1_План_КПи | AO1: Н1_Ост_после_7 | AP1: Н1_План_E-commerce | AQ1: Н1_Ост_после_8 | AR1: Н2_Доступно | AS1: Н2_План_ФС промо | AT1: Н2_Ост_после_1 | AU1: Н2_План_ФС рег | AV1: Н2_Ост_после_2 | AW1: Н2_План_РДЦ | AX1: Н2_Ост_после_3 | AY1: Н2_План_РКП | AZ1: Н2_Ост_после_4 | BA1: Н2_План_ЭК | BB1: Н2_Ост_после_5 | BC1: Н2_План_ФТ | BD1: Н2_Ост_после_6 | BE1: Н2_План_КПи | BF1: Н2_Ост_после_7 | BG1: Н2_План_E-commerce | BH1: Н2_Ост_после_8 | BI1: Н3_Доступно | BJ1: Н3_План_ФС промо | BK1: Н3_Ост_после_1 | BL1: Н3_План_ФС рег | BM1: Н3_Ост_после_2 | BN1: Н3_План_РДЦ | BO1: Н3_Ост_после_3 | BP1: Н3_План_РКП | BQ1: Н3_Ост_после_4 | BR1: Н3_План_ЭК | BS1: Н3_Ост_после_5 | BT1: Н3_План_ФТ | BU1: Н3_Ост_после_6 | BV1: Н3_План_КПи | BW1: Н3_Ост_после_7 | BX1: Н3_План_E-commerce | BY1: Н3_Ост_после_8 | BZ1: Н4_Доступно | CA1: Н4_План_ФС промо | CB1: Н4_Ост_после_1 | CC1: Н4_План_ФС рег | CD1: Н4_Ост_после_2 | CE1: Н4_План_РДЦ | CF1: Н4_Ост_после_3 | CG1: Н4_План_РКП | CH1: Н4_Ост_после_4 | CI1: Н4_План_ЭК | CJ1: Н4_Ост_после_5 | CK1: Н4_План_ФТ | CL1: Н4_Ост_после_6 | CM1: Н4_План_КПи | CN1: Н4_Ост_после_7 | CO1: Н4_План_E-commerce | CP1: Н4_Ост_после_8 | CQ1: Н5_Доступно | CR1: Н5_План_ФС промо | CS1: Н5_Ост_после_1 | CT1: Н5_План_ФС рег | CU1: Н5_Ост_после_2 | CV1: Н5_План_РДЦ | CW1: Н5_Ост_после_3 | CX1: Н5_План_РКП | CY1: Н5_Ост_после_4 | CZ1: Н5_План_ЭК | DA1: Н5_Ост_после_5 | DB1: Н5_План_ФТ | DC1: Н5_Ост_после_6 | DD1: Н5_План_КПи | DE1: Н5_Ост_после_7 | DF1: Н5_План_E-commerce | DG1: Н5_Ост_после_8
A2: ='02_Данные'!B2 | B2: ='02_Данные'!E2 | C2: ='02_Данные'!F2+'02_Данные'!G2+'02_Данные'!H2+'02_Данные'!I2+'02_Данные'!J2+'02_Данные'!K2 | D2: =SUM('02_Данные'!L2:'02_Данные'!AY2) | E2: =MAX(0,D2-C2) | F2: =IF(E2>0.0001,"ДЕФИЦИТ",IF(Y2>0.0001,"ПРОФИЦИТ","БАЛАНС")) | G2: =AB2+AS2+BJ2+CA2+CR2 | H2: =AD2+AU2+BL2+CC2+CT2 | I2: =AF2+AW2+BN2+CE2+CV2 | J2: =AL2+BC2+BT2+CK2+DB2 | K2: =AJ2+BA2+BR2+CI2+CZ2 | L2: =AN2+BE2+BV2+CM2+DD2 | M2: =AP2+BG2+BX2+CO2+DF2 | N2: =AH2+AY2+BP2+CG2+CX2 | O2: =SUM(G2:N2) | P2: =IFERROR(G2*MIN(1,'01_Нормативы'!$C$4/SUM(G$2:G$429)),0) | Q2: =IFERROR(H2*MIN(1,'01_Нормативы'!$C$5/SUM(H$2:H$429)),0) | R2: =IFERROR(I2*MIN(1,'01_Нормативы'!$C$6/SUM(I$2:I$429)),0) | S2: =IFERROR(J2*MIN(1,'01_Нормативы'!$C$7/SUM(J$2:J$429)),0) | T2: =IFERROR(K2*MIN(1,'01_Нормативы'!$C$8/SUM(K$2:K$429)),0) | U2: =IFERROR(L2*MIN(1,'01_Нормативы'!$C$9/SUM(L$2:L$429)),0) | V2: =IFERROR(M2*MIN(1,'01_Нормативы'!$C$10/SUM(M$2:M$429)),0) | W2: =IFERROR(N2*MIN(1,'01_Нормативы'!$C$11/SUM(N$2:N$429)),0) | X2: =SUM(P2:W2) | Y2: =MAX(0,C2-X2) | Z2: =IF(D2=0,100,X2/D2*100) | AA2: ='02_Данные'!F2+'02_Данные'!G2 | AB2: =MIN('02_Данные'!L2,AA2) | AC2: =AA2-AB2 | AD2: =MIN('02_Данные'!M2,AC2) | AE2: =AC2-AD2 | AF2: =MIN('02_Данные'!N2,AE2) | AG2: =AE2-AF2 | AH2: =MIN('02_Данные'!S2,AG2) | AI2: =AG2-AH2 | AJ2: =MIN('02_Данные'!P2,AI2) | AK2: =AI2-AJ2 | AL2: =MIN('02_Данные'!O2,AK2) | AM2: =AK2-AL2 | AN2: =MIN('02_Данные'!Q2,AM2) | AO2: =AM2-AN2 | AP2: =MIN('02_Данные'!R2,AO2) | AQ2: =AO2-AP2 | AR2: =AQ2+'02_Данные'!H2 | AS2: =MIN('02_Данные'!T2,AR2) | AT2: =AR2-AS2 | AU2: =MIN('02_Данные'!U2,AT2) | AV2: =AT2-AU2 | AW2: =MIN('02_Данные'!V2,AV2) | AX2: =AV2-AW2 | AY2: =MIN('02_Данные'!AA2,AX2) | AZ2: =AX2-AY2 | BA2: =MIN('02_Данные'!X2,AZ2) | BB2: =AZ2-BA2 | BC2: =MIN('02_Данные'!W2,BB2) | BD2: =BB2-BC2 | BE2: =MIN('02_Данные'!Y2,BD2) | BF2: =BD2-BE2 | BG2: =MIN('02_Данные'!Z2,BF2) | BH2: =BF2-BG2 | BI2: =BH2+'02_Данные'!I2 | BJ2: =MIN('02_Данные'!AB2,BI2) | BK2: =BI2-BJ2 | BL2: =MIN('02_Данные'!AC2,BK2) | BM2: =BK2-BL2 | BN2: =MIN('02_Данные'!AD2,BM2) | BO2: =BM2-BN2 | BP2: =MIN('02_Данные'!AI2,BO2) | BQ2: =BO2-BP2 | BR2: =MIN('02_Данные'!AF2,BQ2) | BS2: =BQ2-BR2 | BT2: =MIN('02_Данные'!AE2,BS2) | BU2: =BS2-BT2 | BV2: =MIN('02_Данные'!AG2,BU2) | BW2: =BU2-BV2 | BX2: =MIN('02_Данные'!AH2,BW2) | BY2: =BW2-BX2 | BZ2: =BY2+'02_Данные'!J2 | CA2: =MIN('02_Данные'!AJ2,BZ2) | CB2: =BZ2-CA2 | CC2: =MIN('02_Данные'!AK2,CB2) | CD2: =CB2-CC2 | CE2: =MIN('02_Данные'!AL2,CD2) | CF2: =CD2-CE2 | CG2: =MIN('02_Данные'!AQ2,CF2) | CH2: =CF2-CG2 | CI2: =MIN('02_Данные'!AN2,CH2) | CJ2: =CH2-CI2 | CK2: =MIN('02_Данные'!AM2,CJ2) | CL2: =CJ2-CK2 | CM2: =MIN('02_Данные'!AO2,CL2) | CN2: =CL2-CM2 | CO2: =MIN('02_Данные'!AP2,CN2) | CP2: =CN2-CO2 | CQ2: =CP2+'02_Данные'!K2 | CR2: =MIN('02_Данные'!AR2,CQ2) | CS2: =CQ2-CR2 | CT2: =MIN('02_Данные'!AS2,CS2) | CU2: =CS2-CT2 | CV2: =MIN('02_Данные'!AT2,CU2) | CW2: =CU2-CV2 | CX2: =MIN('02_Данные'!AY2,CW2) | CY2: =CW2-CX2 | CZ2: =MIN('02_Данные'!AV2,CY2) | DA2: =CY2-CZ2 | DB2: =MIN('02_Данные'!AU2,DA2) | DC2: =DA2-DB2 | DD2: =MIN('02_Данные'!AW2,DC2) | DE2: =DC2-DD2 | DF2: =MIN('02_Данные'!AX2,DE2) | DG2: =DE2-DF2
A3: ='02_Данные'!B3 | B3: ='02_Данные'!E3 | C3: ='02_Данные'!F3+'02_Данные'!G3+'02_Данные'!H3+'02_Данные'!I3+'02_Данные'!J3+'02_Данные'!K3 | D3: =SUM('02_Данные'!L3:'02_Данные'!AY3) | E3: =MAX(0,D3-C3) | F3: =IF(E3>0.0001,"ДЕФИЦИТ",IF(Y3>0.0001,"ПРОФИЦИТ","БАЛАНС")) | G3: =AB3+AS3+BJ3+CA3+CR3 | H3: =AD3+AU3+BL3+CC3+CT3 | I3: =AF3+AW3+BN3+CE3+CV3 | J3: =AL3+BC3+BT3+CK3+DB3 | K3: =AJ3+BA3+BR3+CI3+CZ3 | L3: =AN3+BE3+BV3+CM3+DD3 | M3: =AP3+BG3+BX3+CO3+DF3 | N3: =AH3+AY3+BP3+CG3+CX3 | O3: =SUM(G3:N3) | P3: =IFERROR(G3*MIN(1,'01_Нормативы'!$C$4/SUM(G$2:G$429)),0) | Q3: =IFERROR(H3*MIN(1,'01_Нормативы'!$C$5/SUM(H$2:H$429)),0) | R3: =IFERROR(I3*MIN(1,'01_Нормативы'!$C$6/SUM(I$2:I$429)),0) | S3: =IFERROR(J3*MIN(1,'01_Нормативы'!$C$7/SUM(J$2:J$429)),0) | T3: =IFERROR(K3*MIN(1,'01_Нормативы'!$C$8/SUM(K$2:K$429)),0) | U3: =IFERROR(L3*MIN(1,'01_Нормативы'!$C$9/SUM(L$2:L$429)),0) | V3: =IFERROR(M3*MIN(1,'01_Нормативы'!$C$10/SUM(M$2:M$429)),0) | W3: =IFERROR(N3*MIN(1,'01_Нормативы'!$C$11/SUM(N$2:N$429)),0) | X3: =SUM(P3:W3) | Y3: =MAX(0,C3-X3) | Z3: =IF(D3=0,100,X3/D3*100) | AA3: ='02_Данные'!F3+'02_Данные'!G3 | AB3: =MIN('02_Данные'!L3,AA3) | AC3: =AA3-AB3 | AD3: =MIN('02_Данные'!M3,AC3) | AE3: =AC3-AD3 | AF3: =MIN('02_Данные'!N3,AE3) | AG3: =AE3-AF3 | AH3: =MIN('02_Данные'!S3,AG3) | AI3: =AG3-AH3 | AJ3: =MIN('02_Данные'!P3,AI3) | AK3: =AI3-AJ3 | AL3: =MIN('02_Данные'!O3,AK3) | AM3: =AK3-AL3 | AN3: =MIN('02_Данные'!Q3,AM3) | AO3: =AM3-AN3 | AP3: =MIN('02_Данные'!R3,AO3) | AQ3: =AO3-AP3 | AR3: =AQ3+'02_Данные'!H3 | AS3: =MIN('02_Данные'!T3,AR3) | AT3: =AR3-AS3 | AU3: =MIN('02_Данные'!U3,AT3) | AV3: =AT3-AU3 | AW3: =MIN('02_Данные'!V3,AV3) | AX3: =AV3-AW3 | AY3: =MIN('02_Данные'!AA3,AX3) | AZ3: =AX3-AY3 | BA3: =MIN('02_Данные'!X3,AZ3) | BB3: =AZ3-BA3 | BC3: =MIN('02_Данные'!W3,BB3) | BD3: =BB3-BC3 | BE3: =MIN('02_Данные'!Y3,BD3) | BF3: =BD3-BE3 | BG3: =MIN('02_Данные'!Z3,BF3) | BH3: =BF3-BG3 | BI3: =BH3+'02_Данные'!I3 | BJ3: =MIN('02_Данные'!AB3,BI3) | BK3: =BI3-BJ3 | BL3: =MIN('02_Данные'!AC3,BK3) | BM3: =BK3-BL3 | BN3: =MIN('02_Данные'!AD3,BM3) | BO3: =BM3-BN3 | BP3: =MIN('02_Данные'!AI3,BO3) | BQ3: =BO3-BP3 | BR3: =MIN('02_Данные'!AF3,BQ3) | BS3: =BQ3-BR3 | BT3: =MIN('02_Данные'!AE3,BS3) | BU3: =BS3-BT3 | BV3: =MIN('02_Данные'!AG3,BU3) | BW3: =BU3-BV3 | BX3: =MIN('02_Данные'!AH3,BW3) | BY3: =BW3-BX3 | BZ3: =BY3+'02_Данные'!J3 | CA3: =MIN('02_Данные'!AJ3,BZ3) | CB3: =BZ3-CA3 | CC3: =MIN('02_Данные'!AK3,CB3) | CD3: =CB3-CC3 | CE3: =MIN('02_Данные'!AL3,CD3) | CF3: =CD3-CE3 | CG3: =MIN('02_Данные'!AQ3,CF3) | CH3: =CF3-CG3 | CI3: =MIN('02_Данные'!AN3,CH3) | CJ3: =CH3-CI3 | CK3: =MIN('02_Данные'!AM3,CJ3) | CL3: =CJ3-CK3 | CM3: =MIN('02_Данные'!AO3,CL3) | CN3: =CL3-CM3 | CO3: =MIN('02_Данные'!AP3,CN3) | CP3: =CN3-CO3 | CQ3: =CP3+'02_Данные'!K3 | CR3: =MIN('02_Данные'!AR3,CQ3) | CS3: =CQ3-CR3 | CT3: =MIN('02_Данные'!AS3,CS3) | CU3: =CS3-CT3 | CV3: =MIN('02_Данные'!AT3,CU3) | CW3: =CU3-CV3 | CX3: =MIN('02_Данные'!AY3,CW3) | CY3: =CW3-CX3 | CZ3: =MIN('02_Данные'!AV3,CY3) | DA3: =CY3-CZ3 | DB3: =MIN('02_Данные'!AU3,DA3) | DC3: =DA3-DB3 | DD3: =MIN('02_Данные'!AW3,DC3) | DE3: =DC3-DD3 | DF3: =MIN('02_Данные'!AX3,DE3) | DG3: =DE3-DF3
A4: ='02_Данные'!B4 | B4: ='02_Данные'!E4 | C4: ='02_Данные'!F4+'02_Данные'!G4+'02_Данные'!H4+'02_Данные'!I4+'02_Данные'!J4+'02_Данные'!K4 | D4: =SUM('02_Данные'!L4:'02_Данные'!AY4) | E4: =MAX(0,D4-C4) | F4: =IF(E4>0.0001,"ДЕФИЦИТ",IF(Y4>0.0001,"ПРОФИЦИТ","БАЛАНС")) | G4: =AB4+AS4+BJ4+CA4+CR4 | H4: =AD4+AU4+BL4+CC4+CT4 | I4: =AF4+AW4+BN4+CE4+CV4 | J4: =AL4+BC4+BT4+CK4+DB4 | K4: =AJ4+BA4+BR4+CI4+CZ4 | L4: =AN4+BE4+BV4+CM4+DD4 | M4: =AP4+BG4+BX4+CO4+DF4 | N4: =AH4+AY4+BP4+CG4+CX4 | O4: =SUM(G4:N4) | P4: =IFERROR(G4*MIN(1,'01_Нормативы'!$C$4/SUM(G$2:G$429)),0) | Q4: =IFERROR(H4*MIN(1,'01_Нормативы'!$C$5/SUM(H$2:H$429)),0) | R4: =IFERROR(I4*MIN(1,'01_Нормативы'!$C$6/SUM(I$2:I$429)),0) | S4: =IFERROR(J4*MIN(1,'01_Нормативы'!$C$7/SUM(J$2:J$429)),0) | T4: =IFERROR(K4*MIN(1,'01_Нормативы'!$C$8/SUM(K$2:K$429)),0) | U4: =IFERROR(L4*MIN(1,'01_Нормативы'!$C$9/SUM(L$2:L$429)),0) | V4: =IFERROR(M4*MIN(1,'01_Нормативы'!$C$10/SUM(M$2:M$429)),0) | W4: =IFERROR(N4*MIN(1,'01_Нормативы'!$C$11/SUM(N$2:N$429)),0) | X4: =SUM(P4:W4) | Y4: =MAX(0,C4-X4) | Z4: =IF(D4=0,100,X4/D4*100) | AA4: ='02_Данные'!F4+'02_Данные'!G4 | AB4: =MIN('02_Данные'!L4,AA4) | AC4: =AA4-AB4 | AD4: =MIN('02_Данные'!M4,AC4) | AE4: =AC4-AD4 | AF4: =MIN('02_Данные'!N4,AE4) | AG4: =AE4-AF4 | AH4: =MIN('02_Данные'!S4,AG4) | AI4: =AG4-AH4 | AJ4: =MIN('02_Данные'!P4,AI4) | AK4: =AI4-AJ4 | AL4: =MIN('02_Данные'!O4,AK4) | AM4: =AK4-AL4 | AN4: =MIN('02_Данные'!Q4,AM4) | AO4: =AM4-AN4 | AP4: =MIN('02_Данные'!R4,AO4) | AQ4: =AO4-AP4 | AR4: =AQ4+'02_Данные'!H4 | AS4: =MIN('02_Данные'!T4,AR4) | AT4: =AR4-AS4 | AU4: =MIN('02_Данные'!U4,AT4) | AV4: =AT4-AU4 | AW4: =MIN('02_Данные'!V4,AV4) | AX4: =AV4-AW4 | AY4: =MIN('02_Данные'!AA4,AX4) | AZ4: =AX4-AY4 | BA4: =MIN('02_Данные'!X4,AZ4) | BB4: =AZ4-BA4 | BC4: =MIN('02_Данные'!W4,BB4) | BD4: =BB4-BC4 | BE4: =MIN('02_Данные'!Y4,BD4) | BF4: =BD4-BE4 | BG4: =MIN('02_Данные'!Z4,BF4) | BH4: =BF4-BG4 | BI4: =BH4+'02_Данные'!I4 | BJ4: =MIN('02_Данные'!AB4,BI4) | BK4: =BI4-BJ4 | BL4: =MIN('02_Данные'!AC4,BK4) | BM4: =BK4-BL4 | BN4: =MIN('02_Данные'!AD4,BM4) | BO4: =BM4-BN4 | BP4: =MIN('02_Данные'!AI4,BO4) | BQ4: =BO4-BP4 | BR4: =MIN('02_Данные'!AF4,BQ4) | BS4: =BQ4-BR4 | BT4: =MIN('02_Данные'!AE4,BS4) | BU4: =BS4-BT4 | BV4: =MIN('02_Данные'!AG4,BU4) | BW4: =BU4-BV4 | BX4: =MIN('02_Данные'!AH4,BW4) | BY4: =BW4-BX4 | BZ4: =BY4+'02_Данные'!J4 | CA4: =MIN('02_Данные'!AJ4,BZ4) | CB4: =BZ4-CA4 | CC4: =MIN('02_Данные'!AK4,CB4) | CD4: =CB4-CC4 | CE4: =MIN('02_Данные'!AL4,CD4) | CF4: =CD4-CE4 | CG4: =MIN('02_Данные'!AQ4,CF4) | CH4: =CF4-CG4 | CI4: =MIN('02_Данные'!AN4,CH4) | CJ4: =CH4-CI4 | CK4: =MIN('02_Данные'!AM4,CJ4) | CL4: =CJ4-CK4 | CM4: =MIN('02_Данные'!AO4,CL4) | CN4: =CL4-CM4 | CO4: =MIN('02_Данные'!AP4,CN4) | CP4: =CN4-CO4 | CQ4: =CP4+'02_Данные'!K4 | CR4: =MIN('02_Данные'!AR4,CQ4) | CS4: =CQ4-CR4 | CT4: =MIN('02_Данные'!AS4,CS4) | CU4: =CS4-CT4 | CV4: =MIN('02_Данные'!AT4,CU4) | CW4: =CU4-CV4 | CX4: =MIN('02_Данные'!AY4,CW4) | CY4: =CW4-CX4 | CZ4: =MIN('02_Данные'!AV4,CY4) | DA4: =CY4-CZ4 | DB4: =MIN('02_Данные'!AU4,DA4) | DC4: =DA4-DB4 | DD4: =MIN('02_Данные'!AW4,DC4) | DE4: =DC4-DD4 | DF4: =MIN('02_Данные'!AX4,DE4) | DG4: =DE4-DF4
A5: ='02_Данные'!B5 | B5: ='02_Данные'!E5 | C5: ='02_Данные'!F5+'02_Данные'!G5+'02_Данные'!H5+'02_Данные'!I5+'02_Данные'!J5+'02_Данные'!K5 | D5: =SUM('02_Данные'!L5:'02_Данные'!AY5) | E5: =MAX(0,D5-C5) | F5: =IF(E5>0.0001,"ДЕФИЦИТ",IF(Y5>0.0001,"ПРОФИЦИТ","БАЛАНС")) | G5: =AB5+AS5+BJ5+CA5+CR5 | H5: =AD5+AU5+BL5+CC5+CT5 | I5: =AF5+AW5+BN5+CE5+CV5 | J5: =AL5+BC5+BT5+CK5+DB5 | K5: =AJ5+BA5+BR5+CI5+CZ5 | L5: =AN5+BE5+BV5+CM5+DD5 | M5: =AP5+BG5+BX5+CO5+DF5 | N5: =AH5+AY5+BP5+CG5+CX5 | O5: =SUM(G5:N5) | P5: =IFERROR(G5*MIN(1,'01_Нормативы'!$C$4/SUM(G$2:G$429)),0) | Q5: =IFERROR(H5*MIN(1,'01_Нормативы'!$C$5/SUM(H$2:H$429)),0) | R5: =IFERROR(I5*MIN(1,'01_Нормативы'!$C$6/SUM(I$2:I$429)),0) | S5: =IFERROR(J5*MIN(1,'01_Нормативы'!$C$7/SUM(J$2:J$429)),0) | T5: =IFERROR(K5*MIN(1,'01_Нормативы'!$C$8/SUM(K$2:K$429)),0) | U5: =IFERROR(L5*MIN(1,'01_Нормативы'!$C$9/SUM(L$2:L$429)),0) | V5: =IFERROR(M5*MIN(1,'01_Нормативы'!$C$10/SUM(M$2:M$429)),0) | W5: =IFERROR(N5*MIN(1,'01_Нормативы'!$C$11/SUM(N$2:N$429)),0) | X5: =SUM(P5:W5) | Y5: =MAX(0,C5-X5) | Z5: =IF(D5=0,100,X5/D5*100) | AA5: ='02_Данные'!F5+'02_Данные'!G5 | AB5: =MIN('02_Данные'!L5,AA5) | AC5: =AA5-AB5 | AD5: =MIN('02_Данные'!M5,AC5) | AE5: =AC5-AD5 | AF5: =MIN('02_Данные'!N5,AE5) | AG5: =AE5-AF5 | AH5: =MIN('02_Данные'!S5,AG5) | AI5: =AG5-AH5 | AJ5: =MIN('02_Данные'!P5,AI5) | AK5: =AI5-AJ5 | AL5: =MIN('02_Данные'!O5,AK5) | AM5: =AK5-AL5 | AN5: =MIN('02_Данные'!Q5,AM5) | AO5: =AM5-AN5 | AP5: =MIN('02_Данные'!R5,AO5) | AQ5: =AO5-AP5 | AR5: =AQ5+'02_Данные'!H5 | AS5: =MIN('02_Данные'!T5,AR5) | AT5: =AR5-AS5 | AU5: =MIN('02_Данные'!U5,AT5) | AV5: =AT5-AU5 | AW5: =MIN('02_Данные'!V5,AV5) | AX5: =AV5-AW5 | AY5: =MIN('02_Данные'!AA5,AX5) | AZ5: =AX5-AY5 | BA5: =MIN('02_Данные'!X5,AZ5) | BB5: =AZ5-BA5 | BC5: =MIN('02_Данные'!W5,BB5) | BD5: =BB5-BC5 | BE5: =MIN('02_Данные'!Y5,BD5) | BF5: =BD5-BE5 | BG5: =MIN('02_Данные'!Z5,BF5) | BH5: =BF5-BG5 | BI5: =BH5+'02_Данные'!I5 | BJ5: =MIN('02_Данные'!AB5,BI5) | BK5: =BI5-BJ5 | BL5: =MIN('02_Данные'!AC5,BK5) | BM5: =BK5-BL5 | BN5: =MIN('02_Данные'!AD5,BM5) | BO5: =BM5-BN5 | BP5: =MIN('02_Данные'!AI5,BO5) | BQ5: =BO5-BP5 | BR5: =MIN('02_Данные'!AF5,BQ5) | BS5: =BQ5-BR5 | BT5: =MIN('02_Данные'!AE5,BS5) | BU5: =BS5-BT5 | BV5: =MIN('02_Данные'!AG5,BU5) | BW5: =BU5-BV5 | BX5: =MIN('02_Данные'!AH5,BW5) | BY5: =BW5-BX5 | BZ5: =BY5+'02_Данные'!J5 | CA5: =MIN('02_Данные'!AJ5,BZ5) | CB5: =BZ5-CA5 | CC5: =MIN('02_Данные'!AK5,CB5) | CD5: =CB5-CC5 | CE5: =MIN('02_Данные'!AL5,CD5) | CF5: =CD5-CE5 | CG5: =MIN('02_Данные'!AQ5,CF5) | CH5: =CF5-CG5 | CI5: =MIN('02_Данные'!AN5,CH5) | CJ5: =CH5-CI5 | CK5: =MIN('02_Данные'!AM5,CJ5) | CL5: =CJ5-CK5 | CM5: =MIN('02_Данные'!AO5,CL5) | CN5: =CL5-CM5 | CO5: =MIN('02_Данные'!AP5,CN5) | CP5: =CN5-CO5 | CQ5: =CP5+'02_Данные'!K5 | CR5: =MIN('02_Данные'!AR5,CQ5) | CS5: =CQ5-CR5 | CT5: =MIN('02_Данные'!AS5,CS5) | CU5: =CS5-CT5 | CV5: =MIN('02_Данные'!AT5,CU5) | CW5: =CU5-CV5 | CX5: =MIN('02_Данные'!AY5,CW5) | CY5: =CW5-CX5 | CZ5: =MIN('02_Данные'!AV5,CY5) | DA5: =CY5-CZ5 | DB5: =MIN('02_Данные'!AU5,DA5) | DC5: =DA5-DB5 | DD5: =MIN('02_Данные'!AW5,DC5) | DE5: =DC5-DD5 | DF5: =MIN('02_Данные'!AX5,DE5) | DG5: =DE5-DF5
A6: ='02_Данные'!B6 | B6: ='02_Данные'!E6 | C6: ='02_Данные'!F6+'02_Данные'!G6+'02_Данные'!H6+'02_Данные'!I6+'02_Данные'!J6+'02_Данные'!K6 | D6: =SUM('02_Данные'!L6:'02_Данные'!AY6) | E6: =MAX(0,D6-C6) | F6: =IF(E6>0.0001,"ДЕФИЦИТ",IF(Y6>0.0001,"ПРОФИЦИТ","БАЛАНС")) | G6: =AB6+AS6+BJ6+CA6+CR6 | H6: =AD6+AU6+BL6+CC6+CT6 | I6: =AF6+AW6+BN6+CE6+CV6 | J6: =AL6+BC6+BT6+CK6+DB6 | K6: =AJ6+BA6+BR6+CI6+CZ6 | L6: =AN6+BE6+BV6+CM6+DD6 | M6: =AP6+BG6+BX6+CO6+DF6 | N6: =AH6+AY6+BP6+CG6+CX6 | O6: =SUM(G6:N6) | P6: =IFERROR(G6*MIN(1,'01_Нормативы'!$C$4/SUM(G$2:G$429)),0) | Q6: =IFERROR(H6*MIN(1,'01_Нормативы'!$C$5/SUM(H$2:H$429)),0) | R6: =IFERROR(I6*MIN(1,'01_Нормативы'!$C$6/SUM(I$2:I$429)),0) | S6: =IFERROR(J6*MIN(1,'01_Нормативы'!$C$7/SUM(J$2:J$429)),0) | T6: =IFERROR(K6*MIN(1,'01_Нормативы'!$C$8/SUM(K$2:K$429)),0) | U6: =IFERROR(L6*MIN(1,'01_Нормативы'!$C$9/SUM(L$2:L$429)),0) | V6: =IFERROR(M6*MIN(1,'01_Нормативы'!$C$10/SUM(M$2:M$429)),0) | W6: =IFERROR(N6*MIN(1,'01_Нормативы'!$C$11/SUM(N$2:N$429)),0) | X6: =SUM(P6:W6) | Y6: =MAX(0,C6-X6) | Z6: =IF(D6=0,100,X6/D6*100) | AA6: ='02_Данные'!F6+'02_Данные'!G6 | AB6: =MIN('02_Данные'!L6,AA6) | AC6: =AA6-AB6 | AD6: =MIN('02_Данные'!M6,AC6) | AE6: =AC6-AD6 | AF6: =MIN('02_Данные'!N6,AE6) | AG6: =AE6-AF6 | AH6: =MIN('02_Данные'!S6,AG6) | AI6: =AG6-AH6 | AJ6: =MIN('02_Данные'!P6,AI6) | AK6: =AI6-AJ6 | AL6: =MIN('02_Данные'!O6,AK6) | AM6: =AK6-AL6 | AN6: =MIN('02_Данные'!Q6,AM6) | AO6: =AM6-AN6 | AP6: =MIN('02_Данные'!R6,AO6) | AQ6: =AO6-AP6 | AR6: =AQ6+'02_Данные'!H6 | AS6: =MIN('02_Данные'!T6,AR6) | AT6: =AR6-AS6 | AU6: =MIN('02_Данные'!U6,AT6) | AV6: =AT6-AU6 | AW6: =MIN('02_Данные'!V6,AV6) | AX6: =AV6-AW6 | AY6: =MIN('02_Данные'!AA6,AX6) | AZ6: =AX6-AY6 | BA6: =MIN('02_Данные'!X6,AZ6) | BB6: =AZ6-BA6 | BC6: =MIN('02_Данные'!W6,BB6) | BD6: =BB6-BC6 | BE6: =MIN('02_Данные'!Y6,BD6) | BF6: =BD6-BE6 | BG6: =MIN('02_Данные'!Z6,BF6) | BH6: =BF6-BG6 | BI6: =BH6+'02_Данные'!I6 | BJ6: =MIN('02_Данные'!AB6,BI6) | BK6: =BI6-BJ6 | BL6: =MIN('02_Данные'!AC6,BK6) | BM6: =BK6-BL6 | BN6: =MIN('02_Данные'!AD6,BM6) | BO6: =BM6-BN6 | BP6: =MIN('02_Данные'!AI6,BO6) | BQ6: =BO6-BP6 | BR6: =MIN('02_Данные'!AF6,BQ6) | BS6: =BQ6-BR6 | BT6: =MIN('02_Данные'!AE6,BS6) | BU6: =BS6-BT6 | BV6: =MIN('02_Данные'!AG6,BU6) | BW6: =BU6-BV6 | BX6: =MIN('02_Данные'!AH6,BW6) | BY6: =BW6-BX6 | BZ6: =BY6+'02_Данные'!J6 | CA6: =MIN('02_Данные'!AJ6,BZ6) | CB6: =BZ6-CA6 | CC6: =MIN('02_Данные'!AK6,CB6) | CD6: =CB6-CC6 | CE6: =MIN('02_Данные'!AL6,CD6) | CF6: =CD6-CE6 | CG6: =MIN('02_Данные'!AQ6,CF6) | CH6: =CF6-CG6 | CI6: =MIN('02_Данные'!AN6,CH6) | CJ6: =CH6-CI6 | CK6: =MIN('02_Данные'!AM6,CJ6) | CL6: =CJ6-CK6 | CM6: =MIN('02_Данные'!AO6,CL6) | CN6: =CL6-CM6 | CO6: =MIN('02_Данные'!AP6,CN6) | CP6: =CN6-CO6 | CQ6: =CP6+'02_Данные'!K6 | CR6: =MIN('02_Данные'!AR6,CQ6) | CS6: =CQ6-CR6 | CT6: =MIN('02_Данные'!AS6,CS6) | CU6: =CS6-CT6 | CV6: =MIN('02_Данные'!AT6,CU6) | CW6: =CU6-CV6 | CX6: =MIN('02_Данные'!AY6,CW6) | CY6: =CW6-CX6 | CZ6: =MIN('02_Данные'!AV6,CY6) | DA6: =CY6-CZ6 | DB6: =MIN('02_Данные'!AU6,DA6) | DC6: =DA6-DB6 | DD6: =MIN('02_Данные'!AW6,DC6) | DE6: =DC6-DD6 | DF6: =MIN('02_Данные'!AX6,DE6) | DG6: =DE6-DF6
A7: ='02_Данные'!B7 | B7: ='02_Данные'!E7 | C7: ='02_Данные'!F7+'02_Данные'!G7+'02_Данные'!H7+'02_Данные'!I7+'02_Данные'!J7+'02_Данные'!K7 | D7: =SUM('02_Данные'!L7:'02_Данные'!AY7) | E7: =MAX(0,D7-C7) | F7: =IF(E7>0.0001,"ДЕФИЦИТ",IF(Y7>0.0001,"ПРОФИЦИТ","БАЛАНС")) | G7: =AB7+AS7+BJ7+CA7+CR7 | H7: =AD7+AU7+BL7+CC7+CT7 | I7: =AF7+AW7+BN7+CE7+CV7 | J7: =AL7+BC7+BT7+CK7+DB7 | K7: =AJ7+BA7+BR7+CI7+CZ7 | L7: =AN7+BE7+BV7+CM7+DD7 | M7: =AP7+BG7+BX7+CO7+DF7 | N7: =AH7+AY7+BP7+CG7+CX7 | O7: =SUM(G7:N7) | P7: =IFERROR(G7*MIN(1,'01_Нормативы'!$C$4/SUM(G$2:G$429)),0) | Q7: =IFERROR(H7*MIN(1,'01_Нормативы'!$C$5/SUM(H$2:H$429)),0) | R7: =IFERROR(I7*MIN(1,'01_Нормативы'!$C$6/SUM(I$2:I$429)),0) | S7: =IFERROR(J7*MIN(1,'01_Нормативы'!$C$7/SUM(J$2:J$429)),0) | T7: =IFERROR(K7*MIN(1,'01_Нормативы'!$C$8/SUM(K$2:K$429)),0) | U7: =IFERROR(L7*MIN(1,'01_Нормативы'!$C$9/SUM(L$2:L$429)),0) | V7: =IFERROR(M7*MIN(1,'01_Нормативы'!$C$10/SUM(M$2:M$429)),0) | W7: =IFERROR(N7*MIN(1,'01_Нормативы'!$C$11/SUM(N$2:N$429)),0) | X7: =SUM(P7:W7) | Y7: =MAX(0,C7-X7) | Z7: =IF(D7=0,100,X7/D7*100) | AA7: ='02_Данные'!F7+'02_Данные'!G7 | AB7: =MIN('02_Данные'!L7,AA7) | AC7: =AA7-AB7 | AD7: =MIN('02_Данные'!M7,AC7) | AE7: =AC7-AD7 | AF7: =MIN('02_Данные'!N7,AE7) | AG7: =AE7-AF7 | AH7: =MIN('02_Данные'!S7,AG7) | AI7: =AG7-AH7 | AJ7: =MIN('02_Данные'!P7,AI7) | AK7: =AI7-AJ7 | AL7: =MIN('02_Данные'!O7,AK7) | AM7: =AK7-AL7 | AN7: =MIN('02_Данные'!Q7,AM7) | AO7: =AM7-AN7 | AP7: =MIN('02_Данные'!R7,AO7) | AQ7: =AO7-AP7 | AR7: =AQ7+'02_Данные'!H7 | AS7: =MIN('02_Данные'!T7,AR7) | AT7: =AR7-AS7 | AU7: =MIN('02_Данные'!U7,AT7) | AV7: =AT7-AU7 | AW7: =MIN('02_Данные'!V7,AV7) | AX7: =AV7-AW7 | AY7: =MIN('02_Данные'!AA7,AX7) | AZ7: =AX7-AY7 | BA7: =MIN('02_Данные'!X7,AZ7) | BB7: =AZ7-BA7 | BC7: =MIN('02_Данные'!W7,BB7) | BD7: =BB7-BC7 | BE7: =MIN('02_Данные'!Y7,BD7) | BF7: =BD7-BE7 | BG7: =MIN('02_Данные'!Z7,BF7) | BH7: =BF7-BG7 | BI7: =BH7+'02_Данные'!I7 | BJ7: =MIN('02_Данные'!AB7,BI7) | BK7: =BI7-BJ7 | BL7: =MIN('02_Данные'!AC7,BK7) | BM7: =BK7-BL7 | BN7: =MIN('02_Данные'!AD7,BM7) | BO7: =BM7-BN7 | BP7: =MIN('02_Данные'!AI7,BO7) | BQ7: =BO7-BP7 | BR7: =MIN('02_Данные'!AF7,BQ7) | BS7: =BQ7-BR7 | BT7: =MIN('02_Данные'!AE7,BS7) | BU7: =BS7-BT7 | BV7: =MIN('02_Данные'!AG7,BU7) | BW7: =BU7-BV7 | BX7: =MIN('02_Данные'!AH7,BW7) | BY7: =BW7-BX7 | BZ7: =BY7+'02_Данные'!J7 | CA7: =MIN('02_Данные'!AJ7,BZ7) | CB7: =BZ7-CA7 | CC7: =MIN('02_Данные'!AK7,CB7) | CD7: =CB7-CC7 | CE7: =MIN('02_Данные'!AL7,CD7) | CF7: =CD7-CE7 | CG7: =MIN('02_Данные'!AQ7,CF7) | CH7: =CF7-CG7 | CI7: =MIN('02_Данные'!AN7,CH7) | CJ7: =CH7-CI7 | CK7: =MIN('02_Данные'!AM7,CJ7) | CL7: =CJ7-CK7 | CM7: =MIN('02_Данные'!AO7,CL7) | CN7: =CL7-CM7 | CO7: =MIN('02_Данные'!AP7,CN7) | CP7: =CN7-CO7 | CQ7: =CP7+'02_Данные'!K7 | CR7: =MIN('02_Данные'!AR7,CQ7) | CS7: =CQ7-CR7 | CT7: =MIN('02_Данные'!AS7,CS7) | CU7: =CS7-CT7 | CV7: =MIN('02_Данные'!AT7,CU7) | CW7: =CU7-CV7 | CX7: =MIN('02_Данные'!AY7,CW7) | CY7: =CW7-CX7 | CZ7: =MIN('02_Данные'!AV7,CY7) | DA7: =CY7-CZ7 | DB7: =MIN('02_Данные'!AU7,DA7) | DC7: =DA7-DB7 | DD7: =MIN('02_Данные'!AW7,DC7) | DE7: =DC7-DD7 | DF7: =MIN('02_Данные'!AX7,DE7) | DG7: =DE7-DF7
A8: ='02_Данные'!B8 | B8: ='02_Данные'!E8 | C8: ='02_Данные'!F8+'02_Данные'!G8+'02_Данные'!H8+'02_Данные'!I8+'02_Данные'!J8+'02_Данные'!K8 | D8: =SUM('02_Данные'!L8:'02_Данные'!AY8) | E8: =MAX(0,D8-C8) | F8: =IF(E8>0.0001,"ДЕФИЦИТ",IF(Y8>0.0001,"ПРОФИЦИТ","БАЛАНС")) | G8: =AB8+AS8+BJ8+CA8+CR8 | H8: =AD8+AU8+BL8+CC8+CT8 | I8: =AF8+AW8+BN8+CE8+CV8 | J8: =AL8+BC8+BT8+CK8+DB8 | K8: =AJ8+BA8+BR8+CI8+CZ8 | L8: =AN8+BE8+BV8+CM8+DD8 | M8: =AP8+BG8+BX8+CO8+DF8 | N8: =AH8+AY8+BP8+CG8+CX8 | O8: =SUM(G8:N8) | P8: =IFERROR(G8*MIN(1,'01_Нормативы'!$C$4/SUM(G$2:G$429)),0) | Q8: =IFERROR(H8*MIN(1,'01_Нормативы'!$C$5/SUM(H$2:H$429)),0) | R8: =IFERROR(I8*MIN(1,'01_Нормативы'!$C$6/SUM(I$2:I$429)),0) | S8: =IFERROR(J8*MIN(1,'01_Нормативы'!$C$7/SUM(J$2:J$429)),0) | T8: =IFERROR(K8*MIN(1,'01_Нормативы'!$C$8/SUM(K$2:K$429)),0) | U8: =IFERROR(L8*MIN(1,'01_Нормативы'!$C$9/SUM(L$2:L$429)),0) | V8: =IFERROR(M8*MIN(1,'01_Нормативы'!$C$10/SUM(M$2:M$429)),0) | W8: =IFERROR(N8*MIN(1,'01_Нормативы'!$C$11/SUM(N$2:N$429)),0) | X8: =SUM(P8:W8) | Y8: =MAX(0,C8-X8) | Z8: =IF(D8=0,100,X8/D8*100) | AA8: ='02_Данные'!F8+'02_Данные'!G8 | AB8: =MIN('02_Данные'!L8,AA8) | AC8: =AA8-AB8 | AD8: =MIN('02_Данные'!M8,AC8) | AE8: =AC8-AD8 | AF8: =MIN('02_Данные'!N8,AE8) | AG8: =AE8-AF8 | AH8: =MIN('02_Данные'!S8,AG8) | AI8: =AG8-AH8 | AJ8: =MIN('02_Данные'!P8,AI8) | AK8: =AI8-AJ8 | AL8: =MIN('02_Данные'!O8,AK8) | AM8: =AK8-AL8 | AN8: =MIN('02_Данные'!Q8,AM8) | AO8: =AM8-AN8 | AP8: =MIN('02_Данные'!R8,AO8) | AQ8: =AO8-AP8 | AR8: =AQ8+'02_Данные'!H8 | AS8: =MIN('02_Данные'!T8,AR8) | AT8: =AR8-AS8 | AU8: =MIN('02_Данные'!U8,AT8) | AV8: =AT8-AU8 | AW8: =MIN('02_Данные'!V8,AV8) | AX8: =AV8-AW8 | AY8: =MIN('02_Данные'!AA8,AX8) | AZ8: =AX8-AY8 | BA8: =MIN('02_Данные'!X8,AZ8) | BB8: =AZ8-BA8 | BC8: =MIN('02_Данные'!W8,BB8) | BD8: =BB8-BC8 | BE8: =MIN('02_Данные'!Y8,BD8) | BF8: =BD8-BE8 | BG8: =MIN('02_Данные'!Z8,BF8) | BH8: =BF8-BG8 | BI8: =BH8+'02_Данные'!I8 | BJ8: =MIN('02_Данные'!AB8,BI8) | BK8: =BI8-BJ8 | BL8: =MIN('02_Данные'!AC8,BK8) | BM8: =BK8-BL8 | BN8: =MIN('02_Данные'!AD8,BM8) | BO8: =BM8-BN8 | BP8: =MIN('02_Данные'!AI8,BO8) | BQ8: =BO8-BP8 | BR8: =MIN('02_Данные'!AF8,BQ8) | BS8: =BQ8-BR8 | BT8: =MIN('02_Данные'!AE8,BS8) | BU8: =BS8-BT8 | BV8: =MIN('02_Данные'!AG8,BU8) | BW8: =BU8-BV8 | BX8: =MIN('02_Данные'!AH8,BW8) | BY8: =BW8-BX8 | BZ8: =BY8+'02_Данные'!J8 | CA8: =MIN('02_Данные'!AJ8,BZ8) | CB8: =BZ8-CA8 | CC8: =MIN('02_Данные'!AK8,CB8) | CD8: =CB8-CC8 | CE8: =MIN('02_Данные'!AL8,CD8) | CF8: =CD8-CE8 | CG8: =MIN('02_Данные'!AQ8,CF8) | CH8: =CF8-CG8 | CI8: =MIN('02_Данные'!AN8,CH8) | CJ8: =CH8-CI8 | CK8: =MIN('02_Данные'!AM8,CJ8) | CL8: =CJ8-CK8 | CM8: =MIN('02_Данные'!AO8,CL8) | CN8: =CL8-CM8 | CO8: =MIN('02_Данные'!AP8,CN8) | CP8: =CN8-CO8 | CQ8: =CP8+'02_Данные'!K8 | CR8: =MIN('02_Данные'!AR8,CQ8) | CS8: =CQ8-CR8 | CT8: =MIN('02_Данные'!AS8,CS8) | CU8: =CS8-CT8 | CV8: =MIN('02_Данные'!AT8,CU8) | CW8: =CU8-CV8 | CX8: =MIN('02_Данные'!AY8,CW8) | CY8: =CW8-CX8 | CZ8: =MIN('02_Данные'!AV8,CY8) | DA8: =CY8-CZ8 | DB8: =MIN('02_Данные'!AU8,DA8) | DC8: =DA8-DB8 | DD8: =MIN('02_Данные'!AW8,DC8) | DE8: =DC8-DD8 | DF8: =MIN('02_Данные'!AX8,DE8) | DG8: =DE8-DF8
A9: ='02_Данные'!B9 | B9: ='02_Данные'!E9 | C9: ='02_Данные'!F9+'02_Данные'!G9+'02_Данные'!H9+'02_Данные'!I9+'02_Данные'!J9+'02_Данные'!K9 | D9: =SUM('02_Данные'!L9:'02_Данные'!AY9) | E9: =MAX(0,D9-C9) | F9: =IF(E9>0.0001,"ДЕФИЦИТ",IF(Y9>0.0001,"ПРОФИЦИТ","БАЛАНС")) | G9: =AB9+AS9+BJ9+CA9+CR9 | H9: =AD9+AU9+BL9+CC9+CT9 | I9: =AF9+AW9+BN9+CE9+CV9 | J9: =AL9+BC9+BT9+CK9+DB9 | K9: =AJ9+BA9+BR9+CI9+CZ9 | L9: =AN9+BE9+BV9+CM9+DD9 | M9: =AP9+BG9+BX9+CO9+DF9 | N9: =AH9+AY9+BP9+CG9+CX9 | O9: =SUM(G9:N9) | P9: =IFERROR(G9*MIN(1,'01_Нормативы'!$C$4/SUM(G$2:G$429)),0) | Q9: =IFERROR(H9*MIN(1,'01_Нормативы'!$C$5/SUM(H$2:H$429)),0) | R9: =IFERROR(I9*MIN(1,'01_Нормативы'!$C$6/SUM(I$2:I$429)),0) | S9: =IFERROR(J9*MIN(1,'01_Нормативы'!$C$7/SUM(J$2:J$429)),0) | T9: =IFERROR(K9*MIN(1,'01_Нормативы'!$C$8/SUM(K$2:K$429)),0) | U9: =IFERROR(L9*MIN(1,'01_Нормативы'!$C$9/SUM(L$2:L$429)),0) | V9: =IFERROR(M9*MIN(1,'01_Нормативы'!$C$10/SUM(M$2:M$429)),0) | W9: =IFERROR(N9*MIN(1,'01_Нормативы'!$C$11/SUM(N$2:N$429)),0) | X9: =SUM(P9:W9) | Y9: =MAX(0,C9-X9) | Z9: =IF(D9=0,100,X9/D9*100) | AA9: ='02_Данные'!F9+'02_Данные'!G9 | AB9: =MIN('02_Данные'!L9,AA9) | AC9: =AA9-AB9 | AD9: =MIN('02_Данные'!M9,AC9) | AE9: =AC9-AD9 | AF9: =MIN('02_Данные'!N9,AE9) | AG9: =AE9-AF9 | AH9: =MIN('02_Данные'!S9,AG9) | AI9: =AG9-AH9 | AJ9: =MIN('02_Данные'!P9,AI9) | AK9: =AI9-AJ9 | AL9: =MIN('02_Данные'!O9,AK9) | AM9: =AK9-AL9 | AN9: =MIN('02_Данные'!Q9,AM9) | AO9: =AM9-AN9 | AP9: =MIN('02_Данные'!R9,AO9) | AQ9: =AO9-AP9 | AR9: =AQ9+'02_Данные'!H9 | AS9: =MIN('02_Данные'!T9,AR9) | AT9: =AR9-AS9 | AU9: =MIN('02_Данные'!U9,AT9) | AV9: =AT9-AU9 | AW9: =MIN('02_Данные'!V9,AV9) | AX9: =AV9-AW9 | AY9: =MIN('02_Данные'!AA9,AX9) | AZ9: =AX9-AY9 | BA9: =MIN('02_Данные'!X9,AZ9) | BB9: =AZ9-BA9 | BC9: =MIN('02_Данные'!W9,BB9) | BD9: =BB9-BC9 | BE9: =MIN('02_Данные'!Y9,BD9) | BF9: =BD9-BE9 | BG9: =MIN('02_Данные'!Z9,BF9) | BH9: =BF9-BG9 | BI9: =BH9+'02_Данные'!I9 | BJ9: =MIN('02_Данные'!AB9,BI9) | BK9: =BI9-BJ9 | BL9: =MIN('02_Данные'!AC9,BK9) | BM9: =BK9-BL9 | BN9: =MIN('02_Данные'!AD9,BM9) | BO9: =BM9-BN9 | BP9: =MIN('02_Данные'!AI9,BO9) | BQ9: =BO9-BP9 | BR9: =MIN('02_Данные'!AF9,BQ9) | BS9: =BQ9-BR9 | BT9: =MIN('02_Данные'!AE9,BS9) | BU9: =BS9-BT9 | BV9: =MIN('02_Данные'!AG9,BU9) | BW9: =BU9-BV9 | BX9: =MIN('02_Данные'!AH9,BW9) | BY9: =BW9-BX9 | BZ9: =BY9+'02_Данные'!J9 | CA9: =MIN('02_Данные'!AJ9,BZ9) | CB9: =BZ9-CA9 | CC9: =MIN('02_Данные'!AK9,CB9) | CD9: =CB9-CC9 | CE9: =MIN('02_Данные'!AL9,CD9) | CF9: =CD9-CE9 | CG9: =MIN('02_Данные'!AQ9,CF9) | CH9: =CF9-CG9 | CI9: =MIN('02_Данные'!AN9,CH9) | CJ9: =CH9-CI9 | CK9: =MIN('02_Данные'!AM9,CJ9) | CL9: =CJ9-CK9 | CM9: =MIN('02_Данные'!AO9,CL9) | CN9: =CL9-CM9 | CO9: =MIN('02_Данные'!AP9,CN9) | CP9: =CN9-CO9 | CQ9: =CP9+'02_Данные'!K9 | CR9: =MIN('02_Данные'!AR9,CQ9) | CS9: =CQ9-CR9 | CT9: =MIN('02_Данные'!AS9,CS9) | CU9: =CS9-CT9 | CV9: =MIN('02_Данные'!AT9,CU9) | CW9: =CU9-CV9 | CX9: =MIN('02_Данные'!AY9,CW9) | CY9: =CW9-CX9 | CZ9: =MIN('02_Данные'!AV9,CY9) | DA9: =CY9-CZ9 | DB9: =MIN('02_Данные'!AU9,DA9) | DC9: =DA9-DB9 | DD9: =MIN('02_Данные'!AW9,DC9) | DE9: =DC9-DD9 | DF9: =MIN('02_Данные'!AX9,DE9) | DG9: =DE9-DF9
A10: ='02_Данные'!B10 | B10: ='02_Данные'!E10 | C10: ='02_Данные'!F10+'02_Данные'!G10+'02_Данные'!H10+'02_Данные'!I10+'02_Данные'!J10+'02_Данные'!K10 | D10: =SUM('02_Данные'!L10:'02_Данные'!AY10) | E10: =MAX(0,D10-C10) | F10: =IF(E10>0.0001,"ДЕФИЦИТ",IF(Y10>0.0001,"ПРОФИЦИТ","БАЛАНС")) | G10: =AB10+AS10+BJ10+CA10+CR10 | H10: =AD10+AU10+BL10+CC10+CT10 | I10: =AF10+AW10+BN10+CE10+CV10 | J10: =AL10+BC10+BT10+CK10+DB10 | K10: =AJ10+BA10+BR10+CI10+CZ10 | L10: =AN10+BE10+BV10+CM10+DD10 | M10: =AP10+BG10+BX10+CO10+DF10 | N10: =AH10+AY10+BP10+CG10+CX10 | O10: =SUM(G10:N10) | P10: =IFERROR(G10*MIN(1,'01_Нормативы'!$C$4/SUM(G$2:G$429)),0) | Q10: =IFERROR(H10*MIN(1,'01_Нормативы'!$C$5/SUM(H$2:H$429)),0) | R10: =IFERROR(I10*MIN(1,'01_Нормативы'!$C$6/SUM(I$2:I$429)),0) | S10: =IFERROR(J10*MIN(1,'01_Нормативы'!$C$7/SUM(J$2:J$429)),0) | T10: =IFERROR(K10*MIN(1,'01_Нормативы'!$C$8/SUM(K$2:K$429)),0) | U10: =IFERROR(L10*MIN(1,'01_Нормативы'!$C$9/SUM(L$2:L$429)),0) | V10: =IFERROR(M10*MIN(1,'01_Нормативы'!$C$10/SUM(M$2:M$429)),0) | W10: =IFERROR(N10*MIN(1,'01_Нормативы'!$C$11/SUM(N$2:N$429)),0) | X10: =SUM(P10:W10) | Y10: =MAX(0,C10-X10) | Z10: =IF(D10=0,100,X10/D10*100) | AA10: ='02_Данные'!F10+'02_Данные'!G10 | AB10: =MIN('02_Данные'!L10,AA10) | AC10: =AA10-AB10 | AD10: =MIN('02_Данные'!M10,AC10) | AE10: =AC10-AD10 | AF10: =MIN('02_Данные'!N10,AE10) | AG10: =AE10-AF10 | AH10: =MIN('02_Данные'!S10,AG10) | AI10: =AG10-AH10 | AJ10: =MIN('02_Данные'!P10,AI10) | AK10: =AI10-AJ10 | AL10: =MIN('02_Данные'!O10,AK10) | AM10: =AK10-AL10 | AN10: =MIN('02_Данные'!Q10,AM10) | AO10: =AM10-AN10 | AP10: =MIN('02_Данные'!R10,AO10) | AQ10: =AO10-AP10 | AR10: =AQ10+'02_Данные'!H10 | AS10: =MIN('02_Данные'!T10,AR10) | AT10: =AR10-AS10 | AU10: =MIN('02_Данные'!U10,AT10) | AV10: =AT10-AU10 | AW10: =MIN('02_Данные'!V10,AV10) | AX10: =AV10-AW10 | AY10: =MIN('02_Данные'!AA10,AX10) | AZ10: =AX10-AY10 | BA10: =MIN('02_Данные'!X10,AZ10) | BB10: =AZ10-BA10 | BC10: =MIN('02_Данные'!W10,BB10) | BD10: =BB10-BC10 | BE10: =MIN('02_Данные'!Y10,BD10) | BF10: =BD10-BE10 | BG10: =MIN('02_Данные'!Z10,BF10) | BH10: =BF10-BG10 | BI10: =BH10+'02_Данные'!I10 | BJ10: =MIN('02_Данные'!AB10,BI10) | BK10: =BI10-BJ10 | BL10: =MIN('02_Данные'!AC10,BK10) | BM10: =BK10-BL10 | BN10: =MIN('02_Данные'!AD10,BM10) | BO10: =BM10-BN10 | BP10: =MIN('02_Данные'!AI10,BO10) | BQ10: =BO10-BP10 | BR10: =MIN('02_Данные'!AF10,BQ10) | BS10: =BQ10-BR10 | BT10: =MIN('02_Данные'!AE10,BS10) | BU10: =BS10-BT10 | BV10: =MIN('02_Данные'!AG10,BU10) | BW10: =BU10-BV10 | BX10: =MIN('02_Данные'!AH10,BW10) | BY10: =BW10-BX10 | BZ10: =BY10+'02_Данные'!J10 | CA10: =MIN('02_Данные'!AJ10,BZ10) | CB10: =BZ10-CA10 | CC10: =MIN('02_Данные'!AK10,CB10) | CD10: =CB10-CC10 | CE10: =MIN('02_Данные'!AL10,CD10) | CF10: =CD10-CE10 | CG10: =MIN('02_Данные'!AQ10,CF10) | CH10: =CF10-CG10 | CI10: =MIN('02_Данные'!AN10,CH10) | CJ10: =CH10-CI10 | CK10: =MIN('02_Данные'!AM10,CJ10) | CL10: =CJ10-CK10 | CM10: =MIN('02_Данные'!AO10,CL10) | CN10: =CL10-CM10 | CO10: =MIN('02_Данные'!AP10,CN10) | CP10: =CN10-CO10 | CQ10: =CP10+'02_Данные'!K10 | CR10: =MIN('02_Данные'!AR10,CQ10) | CS10: =CQ10-CR10 | CT10: =MIN('02_Данные'!AS10,CS10) | CU10: =CS10-CT10 | CV10: =MIN('02_Данные'!AT10,CU10) | CW10: =CU10-CV10 | CX10: =MIN('02_Данные'!AY10,CW10) | CY10: =CW10-CX10 | CZ10: =MIN('02_Данные'!AV10,CY10) | DA10: =CY10-CZ10 | DB10: =MIN('02_Данные'!AU10,DA10) | DC10: =DA10-DB10 | DD10: =MIN('02_Данные'!AW10,DC10) | DE10: =DC10-DD10 | DF10: =MIN('02_Данные'!AX10,DE10) | DG10: =DE10-DF10
A11: ='02_Данные'!B11 | B11: ='02_Данные'!E11 | C11: ='02_Данные'!F11+'02_Данные'!G11+'02_Данные'!H11+'02_Данные'!I11+'02_Данные'!J11+'02_Данные'!K11 | D11: =SUM('02_Данные'!L11:'02_Данные'!AY11) | E11: =MAX(0,D11-C11) | F11: =IF(E11>0.0001,"ДЕФИЦИТ",IF(Y11>0.0001,"ПРОФИЦИТ","БАЛАНС")) | G11: =AB11+AS11+BJ11+CA11+CR11 | H11: =AD11+AU11+BL11+CC11+CT11 | I11: =AF11+AW11+BN11+CE11+CV11 | J11: =AL11+BC11+BT11+CK11+DB11 | K11: =AJ11+BA11+BR11+CI11+CZ11 | L11: =AN11+BE11+BV11+CM11+DD11 | M11: =AP11+BG11+BX11+CO11+DF11 | N11: =AH11+AY11+BP11+CG11+CX11 | O11: =SUM(G11:N11) | P11: =IFERROR(G11*MIN(1,'01_Нормативы'!$C$4/SUM(G$2:G$429)),0) | Q11: =IFERROR(H11*MIN(1,'01_Нормативы'!$C$5/SUM(H$2:H$429)),0) | R11: =IFERROR(I11*MIN(1,'01_Нормативы'!$C$6/SUM(I$2:I$429)),0) | S11: =IFERROR(J11*MIN(1,'01_Нормативы'!$C$7/SUM(J$2:J$429)),0) | T11: =IFERROR(K11*MIN(1,'01_Нормативы'!$C$8/SUM(K$2:K$429)),0) | U11: =IFERROR(L11*MIN(1,'01_Нормативы'!$C$9/SUM(L$2:L$429)),0) | V11: =IFERROR(M11*MIN(1,'01_Нормативы'!$C$10/SUM(M$2:M$429)),0) | W11: =IFERROR(N11*MIN(1,'01_Нормативы'!$C$11/SUM(N$2:N$429)),0) | X11: =SUM(P11:W11) | Y11: =MAX(0,C11-X11) | Z11: =IF(D11=0,100,X11/D11*100) | AA11: ='02_Данные'!F11+'02_Данные'!G11 | AB11: =MIN('02_Данные'!L11,AA11) | AC11: =AA11-AB11 | AD11: =MIN('02_Данные'!M11,AC11) | AE11: =AC11-AD11 | AF11: =MIN('02_Данные'!N11,AE11) | AG11: =AE11-AF11 | AH11: =MIN('02_Данные'!S11,AG11) | AI11: =AG11-AH11 | AJ11: =MIN('02_Данные'!P11,AI11) | AK11: =AI11-AJ11 | AL11: =MIN('02_Данные'!O11,AK11) | AM11: =AK11-AL11 | AN11: =MIN('02_Данные'!Q11,AM11) | AO11: =AM11-AN11 | AP11: =MIN('02_Данные'!R11,AO11) | AQ11: =AO11-AP11 | AR11: =AQ11+'02_Данные'!H11 | AS11: =MIN('02_Данные'!T11,AR11) | AT11: =AR11-AS11 | AU11: =MIN('02_Данные'!U11,AT11) | AV11: =AT11-AU11 | AW11: =MIN('02_Данные'!V11,AV11) | AX11: =AV11-AW11 | AY11: =MIN('02_Данные'!AA11,AX11) | AZ11: =AX11-AY11 | BA11: =MIN('02_Данные'!X11,AZ11) | BB11: =AZ11-BA11 | BC11: =MIN('02_Данные'!W11,BB11) | BD11: =BB11-BC11 | BE11: =MIN('02_Данные'!Y11,BD11) | BF11: =BD11-BE11 | BG11: =MIN('02_Данные'!Z11,BF11) | BH11: =BF11-BG11 | BI11: =BH11+'02_Данные'!I11 | BJ11: =MIN('02_Данные'!AB11,BI11) | BK11: =BI11-BJ11 | BL11: =MIN('02_Данные'!AC11,BK11) | BM11: =BK11-BL11 | BN11: =MIN('02_Данные'!AD11,BM11) | BO11: =BM11-BN11 | BP11: =MIN('02_Данные'!AI11,BO11) | BQ11: =BO11-BP11 | BR11: =MIN('02_Данные'!AF11,BQ11) | BS11: =BQ11-BR11 | BT11: =MIN('02_Данные'!AE11,BS11) | BU11: =BS11-BT11 | BV11: =MIN('02_Данные'!AG11,BU11) | BW11: =BU11-BV11 | BX11: =MIN('02_Данные'!AH11,BW11) | BY11: =BW11-BX11 | BZ11: =BY11+'02_Данные'!J11 | CA11: =MIN('02_Данные'!AJ11,BZ11) | CB11: =BZ11-CA11 | CC11: =MIN('02_Данные'!AK11,CB11) | CD11: =CB11-CC11 | CE11: =MIN('02_Данные'!AL11,CD11) | CF11: =CD11-CE11 | CG11: =MIN('02_Данные'!AQ11,CF11) | CH11: =CF11-CG11 | CI11: =MIN('02_Данные'!AN11,CH11) | CJ11: =CH11-CI11 | CK11: =MIN('02_Данные'!AM11,CJ11) | CL11: =CJ11-CK11 | CM11: =MIN('02_Данные'!AO11,CL11) | CN11: =CL11-CM11 | CO11: =MIN('02_Данные'!AP11,CN11) | CP11: =CN11-CO11 | CQ11: =CP11+'02_Данные'!K11 | CR11: =MIN('02_Данные'!AR11,CQ11) | CS11: =CQ11-CR11 | CT11: =MIN('02_Данные'!AS11,CS11) | CU11: =CS11-CT11 | CV11: =MIN('02_Данные'!AT11,CU11) | CW11: =CU11-CV11 | CX11: =MIN('02_Данные'!AY11,CW11) | CY11: =CW11-CX11 | CZ11: =MIN('02_Данные'!AV11,CY11) | DA11: =CY11-CZ11 | DB11: =MIN('02_Данные'!AU11,DA11) | DC11: =DA11-DB11 | DD11: =MIN('02_Данные'!AW11,DC11) | DE11: =DC11-DD11 | DF11: =MIN('02_Данные'!AX11,DE11) | DG11: =DE11-DF11
A12: ='02_Данные'!B12 | B12: ='02_Данные'!E12 | C12: ='02_Данные'!F12+'02_Данные'!G12+'02_Данные'!H12+'02_Данные'!I12+'02_Данные'!J12+'02_Данные'!K12 | D12: =SUM('02_Данные'!L12:'02_Данные'!AY12) | E12: =MAX(0,D12-C12) | F12: =IF(E12>0.0001,"ДЕФИЦИТ",IF(Y12>0.0001,"ПРОФИЦИТ","БАЛАНС")) | G12: =AB12+AS12+BJ12+CA12+CR12 | H12: =AD12+AU12+BL12+CC12+CT12 | I12: =AF12+AW12+BN12+CE12+CV12 | J12: =AL12+BC12+BT12+CK12+DB12 | K12: =AJ12+BA12+BR12+CI12+CZ12 | L12: =AN12+BE12+BV12+CM12+DD12 | M12: =AP12+BG12+BX12+CO12+DF12 | N12: =AH12+AY12+BP12+CG12+CX12 | O12: =SUM(G12:N12) | P12: =IFERROR(G12*MIN(1,'01_Нормативы'!$C$4/SUM(G$2:G$429)),0) | Q12: =IFERROR(H12*MIN(1,'01_Нормативы'!$C$5/SUM(H$2:H$429)),0) | R12: =IFERROR(I12*MIN(1,'01_Нормативы'!$C$6/SUM(I$2:I$429)),0) | S12: =IFERROR(J12*MIN(1,'01_Нормативы'!$C$7/SUM(J$2:J$429)),0) | T12: =IFERROR(K12*MIN(1,'01_Нормативы'!$C$8/SUM(K$2:K$429)),0) | U12: =IFERROR(L12*MIN(1,'01_Нормативы'!$C$9/SUM(L$2:L$429)),0) | V12: =IFERROR(M12*MIN(1,'01_Нормативы'!$C$10/SUM(M$2:M$429)),0) | W12: =IFERROR(N12*MIN(1,'01_Нормативы'!$C$11/SUM(N$2:N$429)),0) | X12: =SUM(P12:W12) | Y12: =MAX(0,C12-X12) | Z12: =IF(D12=0,100,X12/D12*100) | AA12: ='02_Данные'!F12+'02_Данные'!G12 | AB12: =MIN('02_Данные'!L12,AA12) | AC12: =AA12-AB12 | AD12: =MIN('02_Данные'!M12,AC12) | AE12: =AC12-AD12 | AF12: =MIN('02_Данные'!N12,AE12) | AG12: =AE12-AF12 | AH12: =MIN('02_Данные'!S12,AG12) | AI12: =AG12-AH12 | AJ12: =MIN('02_Данные'!P12,AI12) | AK12: =AI12-AJ12 | AL12: =MIN('02_Данные'!O12,AK12) | AM12: =AK12-AL12 | AN12: =MIN('02_Данные'!Q12,AM12) | AO12: =AM12-AN12 | AP12: =MIN('02_Данные'!R12,AO12) | AQ12: =AO12-AP12 | AR12: =AQ12+'02_Данные'!H12 | AS12: =MIN('02_Данные'!T12,AR12) | AT12: =AR12-AS12 | AU12: =MIN('02_Данные'!U12,AT12) | AV12: =AT12-AU12 | AW12: =MIN('02_Данные'!V12,AV12) | AX12: =AV12-AW12 | AY12: =MIN('02_Данные'!AA12,AX12) | AZ12: =AX12-AY12 | BA12: =MIN('02_Данные'!X12,AZ12) | BB12: =AZ12-BA12 | BC12: =MIN('02_Данные'!W12,BB12) | BD12: =BB12-BC12 | BE12: =MIN('02_Данные'!Y12,BD12) | BF12: =BD12-BE12 | BG12: =MIN('02_Данные'!Z12,BF12) | BH12: =BF12-BG12 | BI12: =BH12+'02_Данные'!I12 | BJ12: =MIN('02_Данные'!AB12,BI12) | BK12: =BI12-BJ12 | BL12: =MIN('02_Данные'!AC12,BK12) | BM12: =BK12-BL12 | BN12: =MIN('02_Данные'!AD12,BM12) | BO12: =BM12-BN12 | BP12: =MIN('02_Данные'!AI12,BO12) | BQ12: =BO12-BP12 | BR12: =MIN('02_Данные'!AF12,BQ12) | BS12: =BQ12-BR12 | BT12: =MIN('02_Данные'!AE12,BS12) | BU12: =BS12-BT12 | BV12: =MIN('02_Данные'!AG12,BU12) | BW12: =BU12-BV12 | BX12: =MIN('02_Данные'!AH12,BW12) | BY12: =BW12-BX12 | BZ12: =BY12+'02_Данные'!J12 | CA12: =MIN('02_Данные'!AJ12,BZ12) | CB12: =BZ12-CA12 | CC12: =MIN('02_Данные'!AK12,CB12) | CD12: =CB12-CC12 | CE12: =MIN('02_Данные'!AL12,CD12) | CF12: =CD12-CE12 | CG12: =MIN('02_Данные'!AQ12,CF12) | CH12: =CF12-CG12 | CI12: =MIN('02_Данные'!AN12,CH12) | CJ12: =CH12-CI12 | CK12: =MIN('02_Данные'!AM12,CJ12) | CL12: =CJ12-CK12 | CM12: =MIN('02_Данные'!AO12,CL12) | CN12: =CL12-CM12 | CO12: =MIN('02_Данные'!AP12,CN12) | CP12: =CN12-CO12 | CQ12: =CP12+'02_Данные'!K12 | CR12: =MIN('02_Данные'!AR12,CQ12) | CS12: =CQ12-CR12 | CT12: =MIN('02_Данные'!AS12,CS12) | CU12: =CS12-CT12 | CV12: =MIN('02_Данные'!AT12,CU12) | CW12: =CU12-CV12 | CX12: =MIN('02_Данные'!AY12,CW12) | CY12: =CW12-CX12 | CZ12: =MIN('02_Данные'!AV12,CY12) | DA12: =CY12-CZ12 | DB12: =MIN('02_Данные'!AU12,DA12) | DC12: =DA12-DB12 | DD12: =MIN('02_Данные'!AW12,DC12) | DE12: =DC12-DD12 | DF12: =MIN('02_Данные'!AX12,DE12) | DG12: =DE12-DF12
A13: ='02_Данные'!B13 | B13: ='02_Данные'!E13 | C13: ='02_Данные'!F13+'02_Данные'!G13+'02_Данные'!H13+'02_Данные'!I13+'02_Данные'!J13+'02_Данные'!K13 | D13: =SUM('02_Данные'!L13:'02_Данные'!AY13) | E13: =MAX(0,D13-C13) | F13: =IF(E13>0.0001,"ДЕФИЦИТ",IF(Y13>0.0001,"ПРОФИЦИТ","БАЛАНС")) | G13: =AB13+AS13+BJ13+CA13+CR13 | H13: =AD13+AU13+BL13+CC13+CT13 | I13: =AF13+AW13+BN13+CE13+CV13 | J13: =AL13+BC13+BT13+CK13+DB13 | K13: =AJ13+BA13+BR13+CI13+CZ13 | L13: =AN13+BE13+BV13+CM13+DD13 | M13: =AP13+BG13+BX13+CO13+DF13 | N13: =AH13+AY13+BP13+CG13+CX13 | O13: =SUM(G13:N13) | P13: =IFERROR(G13*MIN(1,'01_Нормативы'!$C$4/SUM(G$2:G$429)),0) | Q13: =IFERROR(H13*MIN(1,'01_Нормативы'!$C$5/SUM(H$2:H$429)),0) | R13: =IFERROR(I13*MIN(1,'01_Нормативы'!$C$6/SUM(I$2:I$429)),0) | S13: =IFERROR(J13*MIN(1,'01_Нормативы'!$C$7/SUM(J$2:J$429)),0) | T13: =IFERROR(K13*MIN(1,'01_Нормативы'!$C$8/SUM(K$2:K$429)),0) | U13: =IFERROR(L13*MIN(1,'01_Нормативы'!$C$9/SUM(L$2:L$429)),0) | V13: =IFERROR(M13*MIN(1,'01_Нормативы'!$C$10/SUM(M$2:M$429)),0) | W13: =IFERROR(N13*MIN(1,'01_Нормативы'!$C$11/SUM(N$2:N$429)),0) | X13: =SUM(P13:W13) | Y13: =MAX(0,C13-X13) | Z13: =IF(D13=0,100,X13/D13*100) | AA13: ='02_Данные'!F13+'02_Данные'!G13 | AB13: =MIN('02_Данные'!L13,AA13) | AC13: =AA13-AB13 | AD13: =MIN('02_Данные'!M13,AC13) | AE13: =AC13-AD13 | AF13: =MIN('02_Данные'!N13,AE13) | AG13: =AE13-AF13 | AH13: =MIN('02_Данные'!S13,AG13) | AI13: =AG13-AH13 | AJ13: =MIN('02_Данные'!P13,AI13) | AK13: =AI13-AJ13 | AL13: =MIN('02_Данные'!O13,AK13) | AM13: =AK13-AL13 | AN13: =MIN('02_Данные'!Q13,AM13) | AO13: =AM13-AN13 | AP13: =MIN('02_Данные'!R13,AO13) | AQ13: =AO13-AP13 | AR13: =AQ13+'02_Данные'!H13 | AS13: =MIN('02_Данные'!T13,AR13) | AT13: =AR13-AS13 | AU13: =MIN('02_Данные'!U13,AT13) | AV13: =AT13-AU13 | AW13: =MIN('02_Данные'!V13,AV13) | AX13: =AV13-AW13 | AY13: =MIN('02_Данные'!AA13,AX13) | AZ13: =AX13-AY13 | BA13: =MIN('02_Данные'!X13,AZ13) | BB13: =AZ13-BA13 | BC13: =MIN('02_Данные'!W13,BB13) | BD13: =BB13-BC13 | BE13: =MIN('02_Данные'!Y13,BD13) | BF13: =BD13-BE13 | BG13: =MIN('02_Данные'!Z13,BF13) | BH13: =BF13-BG13 | BI13: =BH13+'02_Данные'!I13 | BJ13: =MIN('02_Данные'!AB13,BI13) | BK13: =BI13-BJ13 | BL13: =MIN('02_Данные'!AC13,BK13) | BM13: =BK13-BL13 | BN13: =MIN('02_Данные'!AD13,BM13) | BO13: =BM13-BN13 | BP13: =MIN('02_Данные'!AI13,BO13) | BQ13: =BO13-BP13 | BR13: =MIN('02_Данные'!AF13,BQ13) | BS13: =BQ13-BR13 | BT13: =MIN('02_Данные'!AE13,BS13) | BU13: =BS13-BT13 | BV13: =MIN('02_Данные'!AG13,BU13) | BW13: =BU13-BV13 | BX13: =MIN('02_Данные'!AH13,BW13) | BY13: =BW13-BX13 | BZ13: =BY13+'02_Данные'!J13 | CA13: =MIN('02_Данные'!AJ13,BZ13) | CB13: =BZ13-CA13 | CC13: =MIN('02_Данные'!AK13,CB13) | CD13: =CB13-CC13 | CE13: =MIN('02_Данные'!AL13,CD13) | CF13: =CD13-CE13 | CG13: =MIN('02_Данные'!AQ13,CF13) | CH13: =CF13-CG13 | CI13: =MIN('02_Данные'!AN13,CH13) | CJ13: =CH13-CI13 | CK13: =MIN('02_Данные'!AM13,CJ13) | CL13: =CJ13-CK13 | CM13: =MIN('02_Данные'!AO13,CL13) | CN13: =CL13-CM13 | CO13: =MIN('02_Данные'!AP13,CN13) | CP13: =CN13-CO13 | CQ13: =CP13+'02_Данные'!K13 | CR13: =MIN('02_Данные'!AR13,CQ13) | CS13: =CQ13-CR13 | CT13: =MIN('02_Данные'!AS13,CS13) | CU13: =CS13-CT13 | CV13: =MIN('02_Данные'!AT13,CU13) | CW13: =CU13-CV13 | CX13: =MIN('02_Данные'!AY13,CW13) | CY13: =CW13-CX13 | CZ13: =MIN('02_Данные'!AV13,CY13) | DA13: =CY13-CZ13 | DB13: =MIN('02_Данные'!AU13,DA13) | DC13: =DA13-DB13 | DD13: =MIN('02_Данные'!AW13,DC13) | DE13: =DC13-DD13 | DF13: =MIN('02_Данные'!AX13,DE13) | DG13: =DE13-DF13
... A429: ='02_Данные'!B429 | B429: ='02_Данные'!E429 | C429: ='02_Данные'!F429+'02_Данные'!G429+'02_Данные'!H429+'02_Данные'!I429+'02_Данные'!J429+'02_Данные'!K429 | D429: =SUM('02_Данные'!L429:'02_Данные'!AY429) | E429: =MAX(0,D429-C429) | F429: =IF(E429>0.0001,"ДЕФИЦИТ",IF(Y429>0.0001,"ПРОФИЦИТ","БАЛАНС")) | G429: =AB429+AS429+BJ429+CA429+CR429 | H429: =AD429+AU429+BL429+CC429+CT429 | I429: =AF429+AW429+BN429+CE429+CV429 | J429: =AL429+BC429+BT429+CK429+DB429 | K429: =AJ429+BA429+BR429+CI429+CZ429 | L429: =AN429+BE429+BV429+CM429+DD429 | M429: =AP429+BG429+BX429+CO429+DF429 | N429: =AH429+AY429+BP429+CG429+CX429 | O429: =SUM(G429:N429) | P429: =IFERROR(G429*MIN(1,'01_Нормативы'!$C$4/SUM(G$2:G$429)),0) | Q429: =IFERROR(H429*MIN(1,'01_Нормативы'!$C$5/SUM(H$2:H$429)),0) | R429: =IFERROR(I429*MIN(1,'01_Нормативы'!$C$6/SUM(I$2:I$429)),0) | S429: =IFERROR(J429*MIN(1,'01_Нормативы'!$C$7/SUM(J$2:J$429)),0) | T429: =IFERROR(K429*MIN(1,'01_Нормативы'!$C$8/SUM(K$2:K$429)),0) | U429: =IFERROR(L429*MIN(1,'01_Нормативы'!$C$9/SUM(L$2:L$429)),0) | V429: =IFERROR(M429*MIN(1,'01_Нормативы'!$C$10/SUM(M$2:M$429)),0) | W429: =IFERROR(N429*MIN(1,'01_Нормативы'!$C$11/SUM(N$2:N$429)),0) | X429: =SUM(P429:W429) | Y429: =MAX(0,C429-X429) | Z429: =IF(D429=0,100,X429/D429*100) | AA429: ='02_Данные'!F429+'02_Данные'!G429 | AB429: =MIN('02_Данные'!L429,AA429) | AC429: =AA429-AB429 | AD429: =MIN('02_Данные'!M429,AC429) | AE429: =AC429-AD429 | AF429: =MIN('02_Данные'!N429,AE429) | AG429: =AE429-AF429 | AH429: =MIN('02_Данные'!S429,AG429) | AI429: =AG429-AH429 | AJ429: =MIN('02_Данные'!P429,AI429) | AK429: =AI429-AJ429 | AL429: =MIN('02_Данные'!O429,AK429) | AM429: =AK429-AL429 | AN429: =MIN('02_Данные'!Q429,AM429) | AO429: =AM429-AN429 | AP429: =MIN('02_Данные'!R429,AO429) | AQ429: =AO429-AP429 | AR429: =AQ429+'02_Данные'!H429 | AS429: =MIN('02_Данные'!T429,AR429) | AT429: =AR429-AS429 | AU429: =MIN('02_Данные'!U429,AT429) | AV429: =AT429-AU429 | AW429: =MIN('02_Данные'!V429,AV429) | AX429: =AV429-AW429 | AY429: =MIN('02_Данные'!AA429,AX429) | AZ429: =AX429-AY429 | BA429: =MIN('02_Данные'!X429,AZ429) | BB429: =AZ429-BA429 | BC429: =MIN('02_Данные'!W429,BB429) | BD429: =BB429-BC429 | BE429: =MIN('02_Данные'!Y429,BD429) | BF429: =BD429-BE429 | BG429: =MIN('02_Данные'!Z429,BF429) | BH429: =BF429-BG429 | BI429: =BH429+'02_Данные'!I429 | BJ429: =MIN('02_Данные'!AB429,BI429) | BK429: =BI429-BJ429 | BL429: =MIN('02_Данные'!AC429,BK429) | BM429: =BK429-BL429 | BN429: =MIN('02_Данные'!AD429,BM429) | BO429: =BM429-BN429 | BP429: =MIN('02_Данные'!AI429,BO429) | BQ429: =BO429-BP429 | BR429: =MIN('02_Данные'!AF429,BQ429) | BS429: =BQ429-BR429 | BT429: =MIN('02_Данные'!AE429,BS429) | BU429: =BS429-BT429 | BV429: =MIN('02_Данные'!AG429,BU429) | BW429: =BU429-BV429 | BX429: =MIN('02_Данные'!AH429,BW429) | BY429: =BW429-BX429 | BZ429: =BY429+'02_Данные'!J429 | CA429: =MIN('02_Данные'!AJ429,BZ429) | CB429: =BZ429-CA429 | CC429: =MIN('02_Данные'!AK429,CB429) | CD429: =CB429-CC429 | CE429: =MIN('02_Данные'!AL429,CD429) | CF429: =CD429-CE429 | CG429: =MIN('02_Данные'!AQ429,CF429) | CH429: =CF429-CG429 | CI429: =MIN('02_Данные'!AN429,CH429) | CJ429: =CH429-CI429 | CK429: =MIN('02_Данные'!AM429,CJ429) | CL429: =CJ429-CK429 | CM429: =MIN('02_Данные'!AO429,CL429) | CN429: =CL429-CM429 | CO429: =MIN('02_Данные'!AP429,CN429) | CP429: =CN429-CO429 | CQ429: =CP429+'02_Данные'!K429 | CR429: =MIN('02_Данные'!AR429,CQ429) | CS429: =CQ429-CR429 | CT429: =MIN('02_Данные'!AS429,CS429) | CU429: =CS429-CT429 | CV429: =MIN('02_Данные'!AT429,CU429) | CW429: =CU429-CV429 | CX429: =MIN('02_Данные'!AY429,CW429) | CY429: =CW429-CX429 | CZ429: =MIN('02_Данные'!AV429,CY429) | DA429: =CY429-CZ429 | DB429: =MIN('02_Данные'!AU429,DA429) | DC429: =DA429-DB429 | DD429: =MIN('02_Данные'!AW429,DC429) | DE429: =DC429-DD429 | DF429: =MIN('02_Данные'!AX429,DE429) | DG429: =DE429-DF429
A431: Зелёные ячейки = формулы. Столбцы P-W = итоговый план после урезки до лимита канала (ТЗ). Сырой G-N = до урезки.

Sheet 04_Сводка
A1: Сводка по каналам (всё формулами)
A3: Канал | B3: Цель_т | C3: Цель_кг | D3: Сырой_план_кг | E3: Итоговый_план_кг | F3: Итоговый_план_т | G3: Отклонение_кг | H3: Отклонение_%
A4: ФС промо | B4: ='01_Нормативы'!B4 | C4: ='01_Нормативы'!C4 | D4: =SUM('03_Расчёт'!G2:G429) | E4: =SUM('03_Расчёт'!P2:P429) | F4: =E4/1000 | G4: =E4-C4 | H4: =IF(C4=0,0,(E4/C4-1)*100)
A5: ФС рег | B5: ='01_Нормативы'!B5 | C5: ='01_Нормативы'!C5 | D5: =SUM('03_Расчёт'!H2:H429) | E5: =SUM('03_Расчёт'!Q2:Q429) | F5: =E5/1000 | G5: =E5-C5 | H5: =IF(C5=0,0,(E5/C5-1)*100)
A6: РДЦ | B6: ='01_Нормативы'!B6 | C6: ='01_Нормативы'!C6 | D6: =SUM('03_Расчёт'!I2:I429) | E6: =SUM('03_Расчёт'!R2:R429) | F6: =E6/1000 | G6: =E6-C6 | H6: =IF(C6=0,0,(E6/C6-1)*100)
A7: ФТ | B7: ='01_Нормативы'!B7 | C7: ='01_Нормативы'!C7 | D7: =SUM('03_Расчёт'!J2:J429) | E7: =SUM('03_Расчёт'!S2:S429) | F7: =E7/1000 | G7: =E7-C7 | H7: =IF(C7=0,0,(E7/C7-1)*100)
A8: ЭК | B8: ='01_Нормативы'!B8 | C8: ='01_Нормативы'!C8 | D8: =SUM('03_Расчёт'!K2:K429) | E8: =SUM('03_Расчёт'!T2:T429) | F8: =E8/1000 | G8: =E8-C8 | H8: =IF(C8=0,0,(E8/C8-1)*100)
A9: КПи | B9: ='01_Нормативы'!B9 | C9: ='01_Нормативы'!C9 | D9: =SUM('03_Расчёт'!L2:L429) | E9: =SUM('03_Расчёт'!U2:U429) | F9: =E9/1000 | G9: =E9-C9 | H9: =IF(C9=0,0,(E9/C9-1)*100)
A10: E-commerce | B10: ='01_Нормативы'!B10 | C10: ='01_Нормативы'!C10 | D10: =SUM('03_Расчёт'!M2:M429) | E10: =SUM('03_Расчёт'!V2:V429) | F10: =E10/1000 | G10: =E10-C10 | H10: =IF(C10=0,0,(E10/C10-1)*100)
A11: РКП | B11: ='01_Нормативы'!B11 | C11: ='01_Нормативы'!C11 | D11: =SUM('03_Расчёт'!N2:N429) | E11: =SUM('03_Расчёт'!W2:W429) | F11: =E11/1000 | G11: =E11-C11 | H11: =IF(C11=0,0,(E11/C11-1)*100)
A12: ИТОГО | B12: =SUM(B4:B11) | C12: =SUM(C4:C11) | D12: =SUM(D4:D11) | E12: =SUM(E4:E11) | F12: =SUM(F4:F11) | G12: =SUM(G4:G11)
A14: Проверка: итоговый план канала не должен превышать Цель_кг (отклонение <= 0 с учётом округления).
A15: Число дефицитных SKU: | B15: =COUNTIF('03_Расчёт'!F2:F429,"ДЕФИЦИТ")
A16: Число профицитных SKU: | B16: =COUNTIF('03_Расчёт'!F2:F429,"ПРОФИЦИТ")

Sheet 05_Дефицит
A1: Как пользоваться: на листе 03_Расчёт включи Автофильтр по столбцу «Статус» = ДЕФИЦИТ.
A3: Ниже — формулы, которые подтягивают топ строк с дефицитом (по убыванию). Для сдачи достаточно фильтра на 03.
A5: Код | B5: Тип | C5: Доступно | D5: Спрос | E5: Дефицит | F5: План_итого | G5: Fill_%
A6: Смотри лист 03_Расчёт, столбцы A-F и P-X. Отфильтруй Статус=ДЕФИЦИТ и скопируй видимые строки на лист «К сдаче» при необходимости.
A8: Количество дефицитных: | B8: =COUNTIF('03_Расчёт'!F:F,"ДЕФИЦИТ")
A9: Сумма дефицита, кг: | B9: =SUMIF('03_Расчёт'!F:F,"ДЕФИЦИТ",'03_Расчёт'!E:E)

Sheet 06_Пояснительная
A1: ПОЯСНИТЕЛЬНАЯ ЗАПИСКА (перепиши своими словами перед отправкой)
A3: 1. Список дефицитных позиций
A4: Дефицит = позиции, где остаток на начало + выпуск по неделям < суммы прогноза каналов.
A5: Список: лист 03_Расчёт, фильтр Статус=ДЕФИЦИТ (оранжевый). Количество и сумма — на листе 04/05 (формулы COUNTIF/SUMIF).
A7: 2. Почему распределение именно такое
A8: При нехватке товара действует приоритет каналов: ФС промо → ФС рег → РДЦ → РКП → ЭК → ФТ → КПи → E-commerce.
A9: Расчёт понедельный: доступно = переходящий остаток + выпуск недели; остаток переносится на следующую неделю.
A10: После сборки сырого плана сумма по каналу ограничивается целевым планом канала (тонны×1000) пропорциональным коэффициентом.
A11: План производства не увеличивался. Целевой остаток не использовался.
A13: 3. Риски при дефиците
A14: - Штрафы / cut-off промо и потеря полки в федеральных сетях
